2020-03-20 12:18:48,410 [WARNING]- Not Found: /yo
2020-03-20 12:25:16,241 [ERROR]- Internal Server Error: /
Traceback (most recent call last):
  File "/home/rik/nosedive/venv/lib/python3.6/site-packages/django/core/handlers/exception.py", line 34, in inner
    response = get_response(request)
  File "/home/rik/nosedive/venv/lib/python3.6/site-packages/django/core/handlers/base.py", line 115, in _get_response
    response = self.process_exception_by_middleware(e, request)
  File "/home/rik/nosedive/venv/lib/python3.6/site-packages/django/core/handlers/base.py", line 113, in _get_response
    response = wrapped_callback(request, *callback_args, **callback_kwargs)
  File "/home/rik/nosedive/venv/lib/python3.6/site-packages/django/views/generic/base.py", line 71, in view
    return self.dispatch(request, *args, **kwargs)
  File "/home/rik/nosedive/venv/lib/python3.6/site-packages/django/views/generic/base.py", line 97, in dispatch
    return handler(request, *args, **kwargs)
  File "/home/rik/nosedive/venv/lib/python3.6/site-packages/django/views/generic/base.py", line 158, in get
    context = self.get_context_data(**kwargs)
  File "/home/rik/nosedive/main/views.py", line 25, in get_context_data
    logger.info(self.request.user + " opened /")
TypeError: unsupported operand type(s) for +: 'SimpleLazyObject' and 'str'
2023-10-25 22:14:37,050 [WARNING]- Bad Request: /
2023-10-25 22:14:37,251 [WARNING]- Bad Request: /favicon.ico
2023-10-25 22:15:27,796 [WARNING]- Bad Request: /
2023-10-25 22:15:28,112 [WARNING]- Bad Request: /favicon.ico
2023-10-25 22:21:10,610 [WARNING]- Bad Request: /
2023-10-25 22:21:10,803 [WARNING]- Bad Request: /favicon.ico
2023-10-25 22:33:37,073 [WARNING]- Bad Request: /
2023-10-25 22:56:35,526 [WARNING]- Bad Request: /
2023-10-25 22:56:35,750 [WARNING]- Bad Request: /favicon.ico
2023-10-25 23:01:59,140 [WARNING]- Bad Request: /
2023-10-25 23:01:59,355 [WARNING]- Bad Request: /favicon.ico
2023-10-25 23:03:21,679 [WARNING]- Not Found: /favicon.ico
2023-10-25 23:26:25,546 [WARNING]- Bad Request: /
2023-10-25 23:26:25,853 [WARNING]- Bad Request: /favicon.ico
2023-10-26 09:27:00,282 [WARNING]- Not Found: /favicon.ico
2023-10-26 09:41:59,901 [WARNING]- Bad Request: /
2023-10-26 09:51:57,867 [ERROR]- Internal Server Error: /
Traceback (most recent call last):
  File "C:\Users\My_PC\AppData\Local\Programs\Python\Python311\Lib\site-packages\django\db\backends\utils.py", line 89, in _execute
    return self.cursor.execute(sql, params)
           ^^^^^^^^^^^^^^^^^^^^^^^^^^^^^^^^
  File "C:\Users\My_PC\AppData\Local\Programs\Python\Python311\Lib\site-packages\django\db\backends\mysql\base.py", line 75, in execute
    return self.cursor.execute(query, args)
           ^^^^^^^^^^^^^^^^^^^^^^^^^^^^^^^^
  File "C:\Users\My_PC\AppData\Local\Programs\Python\Python311\Lib\site-packages\MySQLdb\cursors.py", line 179, in execute
    res = self._query(mogrified_query)
          ^^^^^^^^^^^^^^^^^^^^^^^^^^^^
  File "C:\Users\My_PC\AppData\Local\Programs\Python\Python311\Lib\site-packages\MySQLdb\cursors.py", line 330, in _query
    db.query(q)
  File "C:\Users\My_PC\AppData\Local\Programs\Python\Python311\Lib\site-packages\MySQLdb\connections.py", line 255, in query
    _mysql.connection.query(self, query)
MySQLdb.ProgrammingError: (1146, "Table 'users.auth_user' doesn't exist")

The above exception was the direct cause of the following exception:

Traceback (most recent call last):
  File "C:\Users\My_PC\AppData\Local\Programs\Python\Python311\Lib\site-packages\django\core\handlers\exception.py", line 55, in inner
    response = get_response(request)
               ^^^^^^^^^^^^^^^^^^^^^
  File "C:\Users\My_PC\AppData\Local\Programs\Python\Python311\Lib\site-packages\django\core\handlers\base.py", line 220, in _get_response
    response = response.render()
               ^^^^^^^^^^^^^^^^^
  File "C:\Users\My_PC\AppData\Local\Programs\Python\Python311\Lib\site-packages\django\template\response.py", line 114, in render
    self.content = self.rendered_content
                   ^^^^^^^^^^^^^^^^^^^^^
  File "C:\Users\My_PC\AppData\Local\Programs\Python\Python311\Lib\site-packages\django\template\response.py", line 92, in rendered_content
    return template.render(context, self._request)
           ^^^^^^^^^^^^^^^^^^^^^^^^^^^^^^^^^^^^^^^
  File "C:\Users\My_PC\AppData\Local\Programs\Python\Python311\Lib\site-packages\django\template\backends\django.py", line 61, in render
    return self.template.render(context)
           ^^^^^^^^^^^^^^^^^^^^^^^^^^^^^
  File "C:\Users\My_PC\AppData\Local\Programs\Python\Python311\Lib\site-packages\django\template\base.py", line 175, in render
    return self._render(context)
           ^^^^^^^^^^^^^^^^^^^^^
  File "C:\Users\My_PC\AppData\Local\Programs\Python\Python311\Lib\site-packages\django\template\base.py", line 167, in _render
    return self.nodelist.render(context)
           ^^^^^^^^^^^^^^^^^^^^^^^^^^^^^
  File "C:\Users\My_PC\AppData\Local\Programs\Python\Python311\Lib\site-packages\django\template\base.py", line 1005, in render
    return SafeString("".join([node.render_annotated(context) for node in self]))
                              ^^^^^^^^^^^^^^^^^^^^^^^^^^^^^^^^^^^^^^^^^^^^^^^^^
  File "C:\Users\My_PC\AppData\Local\Programs\Python\Python311\Lib\site-packages\django\template\base.py", line 1005, in <listcomp>
    return SafeString("".join([node.render_annotated(context) for node in self]))
                               ^^^^^^^^^^^^^^^^^^^^^^^^^^^^^^
  File "C:\Users\My_PC\AppData\Local\Programs\Python\Python311\Lib\site-packages\django\template\base.py", line 966, in render_annotated
    return self.render(context)
           ^^^^^^^^^^^^^^^^^^^^
  File "C:\Users\My_PC\AppData\Local\Programs\Python\Python311\Lib\site-packages\django\template\loader_tags.py", line 157, in render
    return compiled_parent._render(context)
           ^^^^^^^^^^^^^^^^^^^^^^^^^^^^^^^^
  File "C:\Users\My_PC\AppData\Local\Programs\Python\Python311\Lib\site-packages\django\template\base.py", line 167, in _render
    return self.nodelist.render(context)
           ^^^^^^^^^^^^^^^^^^^^^^^^^^^^^
  File "C:\Users\My_PC\AppData\Local\Programs\Python\Python311\Lib\site-packages\django\template\base.py", line 1005, in render
    return SafeString("".join([node.render_annotated(context) for node in self]))
                              ^^^^^^^^^^^^^^^^^^^^^^^^^^^^^^^^^^^^^^^^^^^^^^^^^
  File "C:\Users\My_PC\AppData\Local\Programs\Python\Python311\Lib\site-packages\django\template\base.py", line 1005, in <listcomp>
    return SafeString("".join([node.render_annotated(context) for node in self]))
                               ^^^^^^^^^^^^^^^^^^^^^^^^^^^^^^
  File "C:\Users\My_PC\AppData\Local\Programs\Python\Python311\Lib\site-packages\django\template\base.py", line 966, in render_annotated
    return self.render(context)
           ^^^^^^^^^^^^^^^^^^^^
  File "C:\Users\My_PC\AppData\Local\Programs\Python\Python311\Lib\site-packages\django\template\loader_tags.py", line 63, in render
    result = block.nodelist.render(context)
             ^^^^^^^^^^^^^^^^^^^^^^^^^^^^^^
  File "C:\Users\My_PC\AppData\Local\Programs\Python\Python311\Lib\site-packages\django\template\base.py", line 1005, in render
    return SafeString("".join([node.render_annotated(context) for node in self]))
                              ^^^^^^^^^^^^^^^^^^^^^^^^^^^^^^^^^^^^^^^^^^^^^^^^^
  File "C:\Users\My_PC\AppData\Local\Programs\Python\Python311\Lib\site-packages\django\template\base.py", line 1005, in <listcomp>
    return SafeString("".join([node.render_annotated(context) for node in self]))
                               ^^^^^^^^^^^^^^^^^^^^^^^^^^^^^^
  File "C:\Users\My_PC\AppData\Local\Programs\Python\Python311\Lib\site-packages\django\template\base.py", line 966, in render_annotated
    return self.render(context)
           ^^^^^^^^^^^^^^^^^^^^
  File "C:\Users\My_PC\AppData\Local\Programs\Python\Python311\Lib\site-packages\django\template\defaulttags.py", line 194, in render
    len_values = len(values)
                 ^^^^^^^^^^^
  File "C:\Users\My_PC\AppData\Local\Programs\Python\Python311\Lib\site-packages\django\db\models\query.py", line 380, in __len__
    self._fetch_all()
  File "C:\Users\My_PC\AppData\Local\Programs\Python\Python311\Lib\site-packages\django\db\models\query.py", line 1881, in _fetch_all
    self._result_cache = list(self._iterable_class(self))
                         ^^^^^^^^^^^^^^^^^^^^^^^^^^^^^^^^
  File "C:\Users\My_PC\AppData\Local\Programs\Python\Python311\Lib\site-packages\django\db\models\query.py", line 91, in __iter__
    results = compiler.execute_sql(
              ^^^^^^^^^^^^^^^^^^^^^
  File "C:\Users\My_PC\AppData\Local\Programs\Python\Python311\Lib\site-packages\django\db\models\sql\compiler.py", line 1562, in execute_sql
    cursor.execute(sql, params)
  File "C:\Users\My_PC\AppData\Local\Programs\Python\Python311\Lib\site-packages\django\db\backends\utils.py", line 102, in execute
    return super().execute(sql, params)
           ^^^^^^^^^^^^^^^^^^^^^^^^^^^^
  File "C:\Users\My_PC\AppData\Local\Programs\Python\Python311\Lib\site-packages\django\db\backends\utils.py", line 67, in execute
    return self._execute_with_wrappers(
           ^^^^^^^^^^^^^^^^^^^^^^^^^^^^
  File "C:\Users\My_PC\AppData\Local\Programs\Python\Python311\Lib\site-packages\django\db\backends\utils.py", line 80, in _execute_with_wrappers
    return executor(sql, params, many, context)
           ^^^^^^^^^^^^^^^^^^^^^^^^^^^^^^^^^^^^
  File "C:\Users\My_PC\AppData\Local\Programs\Python\Python311\Lib\site-packages\django\db\backends\utils.py", line 84, in _execute
    with self.db.wrap_database_errors:
  File "C:\Users\My_PC\AppData\Local\Programs\Python\Python311\Lib\site-packages\django\db\utils.py", line 91, in __exit__
    raise dj_exc_value.with_traceback(traceback) from exc_value
  File "C:\Users\My_PC\AppData\Local\Programs\Python\Python311\Lib\site-packages\django\db\backends\utils.py", line 89, in _execute
    return self.cursor.execute(sql, params)
           ^^^^^^^^^^^^^^^^^^^^^^^^^^^^^^^^
  File "C:\Users\My_PC\AppData\Local\Programs\Python\Python311\Lib\site-packages\django\db\backends\mysql\base.py", line 75, in execute
    return self.cursor.execute(query, args)
           ^^^^^^^^^^^^^^^^^^^^^^^^^^^^^^^^
  File "C:\Users\My_PC\AppData\Local\Programs\Python\Python311\Lib\site-packages\MySQLdb\cursors.py", line 179, in execute
    res = self._query(mogrified_query)
          ^^^^^^^^^^^^^^^^^^^^^^^^^^^^
  File "C:\Users\My_PC\AppData\Local\Programs\Python\Python311\Lib\site-packages\MySQLdb\cursors.py", line 330, in _query
    db.query(q)
  File "C:\Users\My_PC\AppData\Local\Programs\Python\Python311\Lib\site-packages\MySQLdb\connections.py", line 255, in query
    _mysql.connection.query(self, query)
django.db.utils.ProgrammingError: (1146, "Table 'users.auth_user' doesn't exist")
2023-10-26 09:54:07,756 [ERROR]- Internal Server Error: /
Traceback (most recent call last):
  File "C:\Users\My_PC\AppData\Local\Programs\Python\Python311\Lib\site-packages\django\template\base.py", line 505, in parse
    compile_func = self.tags[command]
                   ~~~~~~~~~^^^^^^^^^
KeyError: 'endfor'

During handling of the above exception, another exception occurred:

Traceback (most recent call last):
  File "C:\Users\My_PC\AppData\Local\Programs\Python\Python311\Lib\site-packages\django\core\handlers\exception.py", line 55, in inner
    response = get_response(request)
               ^^^^^^^^^^^^^^^^^^^^^
  File "C:\Users\My_PC\AppData\Local\Programs\Python\Python311\Lib\site-packages\django\core\handlers\base.py", line 220, in _get_response
    response = response.render()
               ^^^^^^^^^^^^^^^^^
  File "C:\Users\My_PC\AppData\Local\Programs\Python\Python311\Lib\site-packages\django\template\response.py", line 114, in render
    self.content = self.rendered_content
                   ^^^^^^^^^^^^^^^^^^^^^
  File "C:\Users\My_PC\AppData\Local\Programs\Python\Python311\Lib\site-packages\django\template\response.py", line 90, in rendered_content
    template = self.resolve_template(self.template_name)
               ^^^^^^^^^^^^^^^^^^^^^^^^^^^^^^^^^^^^^^^^^
  File "C:\Users\My_PC\AppData\Local\Programs\Python\Python311\Lib\site-packages\django\template\response.py", line 72, in resolve_template
    return select_template(template, using=self.using)
           ^^^^^^^^^^^^^^^^^^^^^^^^^^^^^^^^^^^^^^^^^^^
  File "C:\Users\My_PC\AppData\Local\Programs\Python\Python311\Lib\site-packages\django\template\loader.py", line 42, in select_template
    return engine.get_template(template_name)
           ^^^^^^^^^^^^^^^^^^^^^^^^^^^^^^^^^^
  File "C:\Users\My_PC\AppData\Local\Programs\Python\Python311\Lib\site-packages\django\template\backends\django.py", line 33, in get_template
    return Template(self.engine.get_template(template_name), self)
                    ^^^^^^^^^^^^^^^^^^^^^^^^^^^^^^^^^^^^^^^
  File "C:\Users\My_PC\AppData\Local\Programs\Python\Python311\Lib\site-packages\django\template\engine.py", line 175, in get_template
    template, origin = self.find_template(template_name)
                       ^^^^^^^^^^^^^^^^^^^^^^^^^^^^^^^^^
  File "C:\Users\My_PC\AppData\Local\Programs\Python\Python311\Lib\site-packages\django\template\engine.py", line 157, in find_template
    template = loader.get_template(name, skip=skip)
               ^^^^^^^^^^^^^^^^^^^^^^^^^^^^^^^^^^^^
  File "C:\Users\My_PC\AppData\Local\Programs\Python\Python311\Lib\site-packages\django\template\loaders\cached.py", line 57, in get_template
    template = super().get_template(template_name, skip)
               ^^^^^^^^^^^^^^^^^^^^^^^^^^^^^^^^^^^^^^^^^
  File "C:\Users\My_PC\AppData\Local\Programs\Python\Python311\Lib\site-packages\django\template\loaders\base.py", line 28, in get_template
    return Template(
           ^^^^^^^^^
  File "C:\Users\My_PC\AppData\Local\Programs\Python\Python311\Lib\site-packages\django\template\base.py", line 154, in __init__
    self.nodelist = self.compile_nodelist()
                    ^^^^^^^^^^^^^^^^^^^^^^^
  File "C:\Users\My_PC\AppData\Local\Programs\Python\Python311\Lib\site-packages\django\template\base.py", line 200, in compile_nodelist
    return parser.parse()
           ^^^^^^^^^^^^^^
  File "C:\Users\My_PC\AppData\Local\Programs\Python\Python311\Lib\site-packages\django\template\base.py", line 513, in parse
    raise self.error(token, e)
  File "C:\Users\My_PC\AppData\Local\Programs\Python\Python311\Lib\site-packages\django\template\base.py", line 511, in parse
    compiled_result = compile_func(self, token)
                      ^^^^^^^^^^^^^^^^^^^^^^^^^
  File "C:\Users\My_PC\AppData\Local\Programs\Python\Python311\Lib\site-packages\django\template\loader_tags.py", line 293, in do_extends
    nodelist = parser.parse()
               ^^^^^^^^^^^^^^
  File "C:\Users\My_PC\AppData\Local\Programs\Python\Python311\Lib\site-packages\django\template\base.py", line 513, in parse
    raise self.error(token, e)
  File "C:\Users\My_PC\AppData\Local\Programs\Python\Python311\Lib\site-packages\django\template\base.py", line 511, in parse
    compiled_result = compile_func(self, token)
                      ^^^^^^^^^^^^^^^^^^^^^^^^^
  File "C:\Users\My_PC\AppData\Local\Programs\Python\Python311\Lib\site-packages\django\template\loader_tags.py", line 232, in do_block
    nodelist = parser.parse(("endblock",))
               ^^^^^^^^^^^^^^^^^^^^^^^^^^^
  File "C:\Users\My_PC\AppData\Local\Programs\Python\Python311\Lib\site-packages\django\template\base.py", line 507, in parse
    self.invalid_block_tag(token, command, parse_until)
  File "C:\Users\My_PC\AppData\Local\Programs\Python\Python311\Lib\site-packages\django\template\base.py", line 558, in invalid_block_tag
    raise self.error(
django.template.exceptions.TemplateSyntaxError: Invalid block tag on line 50: 'endfor', expected 'endblock'. Did you forget to register or load this tag?
2023-10-26 09:54:08,872 [ERROR]- Internal Server Error: /
Traceback (most recent call last):
  File "C:\Users\My_PC\AppData\Local\Programs\Python\Python311\Lib\site-packages\django\template\base.py", line 505, in parse
    compile_func = self.tags[command]
                   ~~~~~~~~~^^^^^^^^^
KeyError: 'endfor'

During handling of the above exception, another exception occurred:

Traceback (most recent call last):
  File "C:\Users\My_PC\AppData\Local\Programs\Python\Python311\Lib\site-packages\django\core\handlers\exception.py", line 55, in inner
    response = get_response(request)
               ^^^^^^^^^^^^^^^^^^^^^
  File "C:\Users\My_PC\AppData\Local\Programs\Python\Python311\Lib\site-packages\django\core\handlers\base.py", line 220, in _get_response
    response = response.render()
               ^^^^^^^^^^^^^^^^^
  File "C:\Users\My_PC\AppData\Local\Programs\Python\Python311\Lib\site-packages\django\template\response.py", line 114, in render
    self.content = self.rendered_content
                   ^^^^^^^^^^^^^^^^^^^^^
  File "C:\Users\My_PC\AppData\Local\Programs\Python\Python311\Lib\site-packages\django\template\response.py", line 90, in rendered_content
    template = self.resolve_template(self.template_name)
               ^^^^^^^^^^^^^^^^^^^^^^^^^^^^^^^^^^^^^^^^^
  File "C:\Users\My_PC\AppData\Local\Programs\Python\Python311\Lib\site-packages\django\template\response.py", line 72, in resolve_template
    return select_template(template, using=self.using)
           ^^^^^^^^^^^^^^^^^^^^^^^^^^^^^^^^^^^^^^^^^^^
  File "C:\Users\My_PC\AppData\Local\Programs\Python\Python311\Lib\site-packages\django\template\loader.py", line 42, in select_template
    return engine.get_template(template_name)
           ^^^^^^^^^^^^^^^^^^^^^^^^^^^^^^^^^^
  File "C:\Users\My_PC\AppData\Local\Programs\Python\Python311\Lib\site-packages\django\template\backends\django.py", line 33, in get_template
    return Template(self.engine.get_template(template_name), self)
                    ^^^^^^^^^^^^^^^^^^^^^^^^^^^^^^^^^^^^^^^
  File "C:\Users\My_PC\AppData\Local\Programs\Python\Python311\Lib\site-packages\django\template\engine.py", line 175, in get_template
    template, origin = self.find_template(template_name)
                       ^^^^^^^^^^^^^^^^^^^^^^^^^^^^^^^^^
  File "C:\Users\My_PC\AppData\Local\Programs\Python\Python311\Lib\site-packages\django\template\engine.py", line 157, in find_template
    template = loader.get_template(name, skip=skip)
               ^^^^^^^^^^^^^^^^^^^^^^^^^^^^^^^^^^^^
  File "C:\Users\My_PC\AppData\Local\Programs\Python\Python311\Lib\site-packages\django\template\loaders\cached.py", line 57, in get_template
    template = super().get_template(template_name, skip)
               ^^^^^^^^^^^^^^^^^^^^^^^^^^^^^^^^^^^^^^^^^
  File "C:\Users\My_PC\AppData\Local\Programs\Python\Python311\Lib\site-packages\django\template\loaders\base.py", line 28, in get_template
    return Template(
           ^^^^^^^^^
  File "C:\Users\My_PC\AppData\Local\Programs\Python\Python311\Lib\site-packages\django\template\base.py", line 154, in __init__
    self.nodelist = self.compile_nodelist()
                    ^^^^^^^^^^^^^^^^^^^^^^^
  File "C:\Users\My_PC\AppData\Local\Programs\Python\Python311\Lib\site-packages\django\template\base.py", line 200, in compile_nodelist
    return parser.parse()
           ^^^^^^^^^^^^^^
  File "C:\Users\My_PC\AppData\Local\Programs\Python\Python311\Lib\site-packages\django\template\base.py", line 513, in parse
    raise self.error(token, e)
  File "C:\Users\My_PC\AppData\Local\Programs\Python\Python311\Lib\site-packages\django\template\base.py", line 511, in parse
    compiled_result = compile_func(self, token)
                      ^^^^^^^^^^^^^^^^^^^^^^^^^
  File "C:\Users\My_PC\AppData\Local\Programs\Python\Python311\Lib\site-packages\django\template\loader_tags.py", line 293, in do_extends
    nodelist = parser.parse()
               ^^^^^^^^^^^^^^
  File "C:\Users\My_PC\AppData\Local\Programs\Python\Python311\Lib\site-packages\django\template\base.py", line 513, in parse
    raise self.error(token, e)
  File "C:\Users\My_PC\AppData\Local\Programs\Python\Python311\Lib\site-packages\django\template\base.py", line 511, in parse
    compiled_result = compile_func(self, token)
                      ^^^^^^^^^^^^^^^^^^^^^^^^^
  File "C:\Users\My_PC\AppData\Local\Programs\Python\Python311\Lib\site-packages\django\template\loader_tags.py", line 232, in do_block
    nodelist = parser.parse(("endblock",))
               ^^^^^^^^^^^^^^^^^^^^^^^^^^^
  File "C:\Users\My_PC\AppData\Local\Programs\Python\Python311\Lib\site-packages\django\template\base.py", line 507, in parse
    self.invalid_block_tag(token, command, parse_until)
  File "C:\Users\My_PC\AppData\Local\Programs\Python\Python311\Lib\site-packages\django\template\base.py", line 558, in invalid_block_tag
    raise self.error(
django.template.exceptions.TemplateSyntaxError: Invalid block tag on line 50: 'endfor', expected 'endblock'. Did you forget to register or load this tag?
2023-10-26 09:54:33,107 [ERROR]- Internal Server Error: /
Traceback (most recent call last):
  File "C:\Users\My_PC\AppData\Local\Programs\Python\Python311\Lib\site-packages\django\db\backends\utils.py", line 89, in _execute
    return self.cursor.execute(sql, params)
           ^^^^^^^^^^^^^^^^^^^^^^^^^^^^^^^^
  File "C:\Users\My_PC\AppData\Local\Programs\Python\Python311\Lib\site-packages\django\db\backends\mysql\base.py", line 75, in execute
    return self.cursor.execute(query, args)
           ^^^^^^^^^^^^^^^^^^^^^^^^^^^^^^^^
  File "C:\Users\My_PC\AppData\Local\Programs\Python\Python311\Lib\site-packages\MySQLdb\cursors.py", line 179, in execute
    res = self._query(mogrified_query)
          ^^^^^^^^^^^^^^^^^^^^^^^^^^^^
  File "C:\Users\My_PC\AppData\Local\Programs\Python\Python311\Lib\site-packages\MySQLdb\cursors.py", line 330, in _query
    db.query(q)
  File "C:\Users\My_PC\AppData\Local\Programs\Python\Python311\Lib\site-packages\MySQLdb\connections.py", line 255, in query
    _mysql.connection.query(self, query)
MySQLdb.ProgrammingError: (1146, "Table 'users.auth_user' doesn't exist")

The above exception was the direct cause of the following exception:

Traceback (most recent call last):
  File "C:\Users\My_PC\AppData\Local\Programs\Python\Python311\Lib\site-packages\django\core\handlers\exception.py", line 55, in inner
    response = get_response(request)
               ^^^^^^^^^^^^^^^^^^^^^
  File "C:\Users\My_PC\AppData\Local\Programs\Python\Python311\Lib\site-packages\django\core\handlers\base.py", line 197, in _get_response
    response = wrapped_callback(request, *callback_args, **callback_kwargs)
               ^^^^^^^^^^^^^^^^^^^^^^^^^^^^^^^^^^^^^^^^^^^^^^^^^^^^^^^^^^^^
  File "C:\Users\My_PC\AppData\Local\Programs\Python\Python311\Lib\site-packages\django\views\generic\base.py", line 104, in view
    return self.dispatch(request, *args, **kwargs)
           ^^^^^^^^^^^^^^^^^^^^^^^^^^^^^^^^^^^^^^^
  File "C:\Users\My_PC\AppData\Local\Programs\Python\Python311\Lib\site-packages\django\views\generic\base.py", line 143, in dispatch
    return handler(request, *args, **kwargs)
           ^^^^^^^^^^^^^^^^^^^^^^^^^^^^^^^^^
  File "C:\Users\My_PC\Desktop\nosedive-master\main\views.py", line 41, in post
    rated_user = User.objects.get(username=data['rated_user'])
                 ^^^^^^^^^^^^^^^^^^^^^^^^^^^^^^^^^^^^^^^^^^^^^
  File "C:\Users\My_PC\AppData\Local\Programs\Python\Python311\Lib\site-packages\django\db\models\manager.py", line 87, in manager_method
    return getattr(self.get_queryset(), name)(*args, **kwargs)
           ^^^^^^^^^^^^^^^^^^^^^^^^^^^^^^^^^^^^^^^^^^^^^^^^^^^
  File "C:\Users\My_PC\AppData\Local\Programs\Python\Python311\Lib\site-packages\django\db\models\query.py", line 633, in get
    num = len(clone)
          ^^^^^^^^^^
  File "C:\Users\My_PC\AppData\Local\Programs\Python\Python311\Lib\site-packages\django\db\models\query.py", line 380, in __len__
    self._fetch_all()
  File "C:\Users\My_PC\AppData\Local\Programs\Python\Python311\Lib\site-packages\django\db\models\query.py", line 1881, in _fetch_all
    self._result_cache = list(self._iterable_class(self))
                         ^^^^^^^^^^^^^^^^^^^^^^^^^^^^^^^^
  File "C:\Users\My_PC\AppData\Local\Programs\Python\Python311\Lib\site-packages\django\db\models\query.py", line 91, in __iter__
    results = compiler.execute_sql(
              ^^^^^^^^^^^^^^^^^^^^^
  File "C:\Users\My_PC\AppData\Local\Programs\Python\Python311\Lib\site-packages\django\db\models\sql\compiler.py", line 1562, in execute_sql
    cursor.execute(sql, params)
  File "C:\Users\My_PC\AppData\Local\Programs\Python\Python311\Lib\site-packages\django\db\backends\utils.py", line 102, in execute
    return super().execute(sql, params)
           ^^^^^^^^^^^^^^^^^^^^^^^^^^^^
  File "C:\Users\My_PC\AppData\Local\Programs\Python\Python311\Lib\site-packages\django\db\backends\utils.py", line 67, in execute
    return self._execute_with_wrappers(
           ^^^^^^^^^^^^^^^^^^^^^^^^^^^^
  File "C:\Users\My_PC\AppData\Local\Programs\Python\Python311\Lib\site-packages\django\db\backends\utils.py", line 80, in _execute_with_wrappers
    return executor(sql, params, many, context)
           ^^^^^^^^^^^^^^^^^^^^^^^^^^^^^^^^^^^^
  File "C:\Users\My_PC\AppData\Local\Programs\Python\Python311\Lib\site-packages\django\db\backends\utils.py", line 84, in _execute
    with self.db.wrap_database_errors:
  File "C:\Users\My_PC\AppData\Local\Programs\Python\Python311\Lib\site-packages\django\db\utils.py", line 91, in __exit__
    raise dj_exc_value.with_traceback(traceback) from exc_value
  File "C:\Users\My_PC\AppData\Local\Programs\Python\Python311\Lib\site-packages\django\db\backends\utils.py", line 89, in _execute
    return self.cursor.execute(sql, params)
           ^^^^^^^^^^^^^^^^^^^^^^^^^^^^^^^^
  File "C:\Users\My_PC\AppData\Local\Programs\Python\Python311\Lib\site-packages\django\db\backends\mysql\base.py", line 75, in execute
    return self.cursor.execute(query, args)
           ^^^^^^^^^^^^^^^^^^^^^^^^^^^^^^^^
  File "C:\Users\My_PC\AppData\Local\Programs\Python\Python311\Lib\site-packages\MySQLdb\cursors.py", line 179, in execute
    res = self._query(mogrified_query)
          ^^^^^^^^^^^^^^^^^^^^^^^^^^^^
  File "C:\Users\My_PC\AppData\Local\Programs\Python\Python311\Lib\site-packages\MySQLdb\cursors.py", line 330, in _query
    db.query(q)
  File "C:\Users\My_PC\AppData\Local\Programs\Python\Python311\Lib\site-packages\MySQLdb\connections.py", line 255, in query
    _mysql.connection.query(self, query)
django.db.utils.ProgrammingError: (1146, "Table 'users.auth_user' doesn't exist")
2023-10-26 09:54:50,584 [ERROR]- Internal Server Error: /accounts/login/
Traceback (most recent call last):
  File "C:\Users\My_PC\AppData\Local\Programs\Python\Python311\Lib\site-packages\django\db\backends\utils.py", line 89, in _execute
    return self.cursor.execute(sql, params)
           ^^^^^^^^^^^^^^^^^^^^^^^^^^^^^^^^
  File "C:\Users\My_PC\AppData\Local\Programs\Python\Python311\Lib\site-packages\django\db\backends\mysql\base.py", line 75, in execute
    return self.cursor.execute(query, args)
           ^^^^^^^^^^^^^^^^^^^^^^^^^^^^^^^^
  File "C:\Users\My_PC\AppData\Local\Programs\Python\Python311\Lib\site-packages\MySQLdb\cursors.py", line 179, in execute
    res = self._query(mogrified_query)
          ^^^^^^^^^^^^^^^^^^^^^^^^^^^^
  File "C:\Users\My_PC\AppData\Local\Programs\Python\Python311\Lib\site-packages\MySQLdb\cursors.py", line 330, in _query
    db.query(q)
  File "C:\Users\My_PC\AppData\Local\Programs\Python\Python311\Lib\site-packages\MySQLdb\connections.py", line 255, in query
    _mysql.connection.query(self, query)
MySQLdb.ProgrammingError: (1146, "Table 'users.auth_user' doesn't exist")

The above exception was the direct cause of the following exception:

Traceback (most recent call last):
  File "C:\Users\My_PC\AppData\Local\Programs\Python\Python311\Lib\site-packages\django\core\handlers\exception.py", line 55, in inner
    response = get_response(request)
               ^^^^^^^^^^^^^^^^^^^^^
  File "C:\Users\My_PC\AppData\Local\Programs\Python\Python311\Lib\site-packages\django\core\handlers\base.py", line 197, in _get_response
    response = wrapped_callback(request, *callback_args, **callback_kwargs)
               ^^^^^^^^^^^^^^^^^^^^^^^^^^^^^^^^^^^^^^^^^^^^^^^^^^^^^^^^^^^^
  File "C:\Users\My_PC\AppData\Local\Programs\Python\Python311\Lib\site-packages\django\views\generic\base.py", line 104, in view
    return self.dispatch(request, *args, **kwargs)
           ^^^^^^^^^^^^^^^^^^^^^^^^^^^^^^^^^^^^^^^
  File "C:\Users\My_PC\AppData\Local\Programs\Python\Python311\Lib\site-packages\django\utils\decorators.py", line 46, in _wrapper
    return bound_method(*args, **kwargs)
           ^^^^^^^^^^^^^^^^^^^^^^^^^^^^^
  File "C:\Users\My_PC\AppData\Local\Programs\Python\Python311\Lib\site-packages\django\views\decorators\debug.py", line 92, in sensitive_post_parameters_wrapper
    return view(request, *args, **kwargs)
           ^^^^^^^^^^^^^^^^^^^^^^^^^^^^^^
  File "C:\Users\My_PC\AppData\Local\Programs\Python\Python311\Lib\site-packages\django\utils\decorators.py", line 46, in _wrapper
    return bound_method(*args, **kwargs)
           ^^^^^^^^^^^^^^^^^^^^^^^^^^^^^
  File "C:\Users\My_PC\AppData\Local\Programs\Python\Python311\Lib\site-packages\django\utils\decorators.py", line 134, in _wrapper_view
    response = view_func(request, *args, **kwargs)
               ^^^^^^^^^^^^^^^^^^^^^^^^^^^^^^^^^^^
  File "C:\Users\My_PC\AppData\Local\Programs\Python\Python311\Lib\site-packages\django\utils\decorators.py", line 46, in _wrapper
    return bound_method(*args, **kwargs)
           ^^^^^^^^^^^^^^^^^^^^^^^^^^^^^
  File "C:\Users\My_PC\AppData\Local\Programs\Python\Python311\Lib\site-packages\django\views\decorators\cache.py", line 62, in _wrapper_view_func
    response = view_func(request, *args, **kwargs)
               ^^^^^^^^^^^^^^^^^^^^^^^^^^^^^^^^^^^
  File "C:\Users\My_PC\AppData\Local\Programs\Python\Python311\Lib\site-packages\django\contrib\auth\views.py", line 90, in dispatch
    return super().dispatch(request, *args, **kwargs)
           ^^^^^^^^^^^^^^^^^^^^^^^^^^^^^^^^^^^^^^^^^^
  File "C:\Users\My_PC\AppData\Local\Programs\Python\Python311\Lib\site-packages\django\views\generic\base.py", line 143, in dispatch
    return handler(request, *args, **kwargs)
           ^^^^^^^^^^^^^^^^^^^^^^^^^^^^^^^^^
  File "C:\Users\My_PC\AppData\Local\Programs\Python\Python311\Lib\site-packages\django\views\generic\edit.py", line 152, in post
    if form.is_valid():
       ^^^^^^^^^^^^^^^
  File "C:\Users\My_PC\AppData\Local\Programs\Python\Python311\Lib\site-packages\django\forms\forms.py", line 201, in is_valid
    return self.is_bound and not self.errors
                                 ^^^^^^^^^^^
  File "C:\Users\My_PC\AppData\Local\Programs\Python\Python311\Lib\site-packages\django\forms\forms.py", line 196, in errors
    self.full_clean()
  File "C:\Users\My_PC\AppData\Local\Programs\Python\Python311\Lib\site-packages\django\forms\forms.py", line 434, in full_clean
    self._clean_form()
  File "C:\Users\My_PC\AppData\Local\Programs\Python\Python311\Lib\site-packages\django\forms\forms.py", line 455, in _clean_form
    cleaned_data = self.clean()
                   ^^^^^^^^^^^^
  File "C:\Users\My_PC\AppData\Local\Programs\Python\Python311\Lib\site-packages\django\contrib\auth\forms.py", line 242, in clean
    self.user_cache = authenticate(
                      ^^^^^^^^^^^^^
  File "C:\Users\My_PC\AppData\Local\Programs\Python\Python311\Lib\site-packages\django\views\decorators\debug.py", line 42, in sensitive_variables_wrapper
    return func(*func_args, **func_kwargs)
           ^^^^^^^^^^^^^^^^^^^^^^^^^^^^^^^
  File "C:\Users\My_PC\AppData\Local\Programs\Python\Python311\Lib\site-packages\django\contrib\auth\__init__.py", line 77, in authenticate
    user = backend.authenticate(request, **credentials)
           ^^^^^^^^^^^^^^^^^^^^^^^^^^^^^^^^^^^^^^^^^^^^
  File "C:\Users\My_PC\AppData\Local\Programs\Python\Python311\Lib\site-packages\django\contrib\auth\backends.py", line 46, in authenticate
    user = UserModel._default_manager.get_by_natural_key(username)
           ^^^^^^^^^^^^^^^^^^^^^^^^^^^^^^^^^^^^^^^^^^^^^^^^^^^^^^^
  File "C:\Users\My_PC\AppData\Local\Programs\Python\Python311\Lib\site-packages\django\contrib\auth\base_user.py", line 54, in get_by_natural_key
    return self.get(**{self.model.USERNAME_FIELD: username})
           ^^^^^^^^^^^^^^^^^^^^^^^^^^^^^^^^^^^^^^^^^^^^^^^^^
  File "C:\Users\My_PC\AppData\Local\Programs\Python\Python311\Lib\site-packages\django\db\models\manager.py", line 87, in manager_method
    return getattr(self.get_queryset(), name)(*args, **kwargs)
           ^^^^^^^^^^^^^^^^^^^^^^^^^^^^^^^^^^^^^^^^^^^^^^^^^^^
  File "C:\Users\My_PC\AppData\Local\Programs\Python\Python311\Lib\site-packages\django\db\models\query.py", line 633, in get
    num = len(clone)
          ^^^^^^^^^^
  File "C:\Users\My_PC\AppData\Local\Programs\Python\Python311\Lib\site-packages\django\db\models\query.py", line 380, in __len__
    self._fetch_all()
  File "C:\Users\My_PC\AppData\Local\Programs\Python\Python311\Lib\site-packages\django\db\models\query.py", line 1881, in _fetch_all
    self._result_cache = list(self._iterable_class(self))
                         ^^^^^^^^^^^^^^^^^^^^^^^^^^^^^^^^
  File "C:\Users\My_PC\AppData\Local\Programs\Python\Python311\Lib\site-packages\django\db\models\query.py", line 91, in __iter__
    results = compiler.execute_sql(
              ^^^^^^^^^^^^^^^^^^^^^
  File "C:\Users\My_PC\AppData\Local\Programs\Python\Python311\Lib\site-packages\django\db\models\sql\compiler.py", line 1562, in execute_sql
    cursor.execute(sql, params)
  File "C:\Users\My_PC\AppData\Local\Programs\Python\Python311\Lib\site-packages\django\db\backends\utils.py", line 102, in execute
    return super().execute(sql, params)
           ^^^^^^^^^^^^^^^^^^^^^^^^^^^^
  File "C:\Users\My_PC\AppData\Local\Programs\Python\Python311\Lib\site-packages\django\db\backends\utils.py", line 67, in execute
    return self._execute_with_wrappers(
           ^^^^^^^^^^^^^^^^^^^^^^^^^^^^
  File "C:\Users\My_PC\AppData\Local\Programs\Python\Python311\Lib\site-packages\django\db\backends\utils.py", line 80, in _execute_with_wrappers
    return executor(sql, params, many, context)
           ^^^^^^^^^^^^^^^^^^^^^^^^^^^^^^^^^^^^
  File "C:\Users\My_PC\AppData\Local\Programs\Python\Python311\Lib\site-packages\django\db\backends\utils.py", line 84, in _execute
    with self.db.wrap_database_errors:
  File "C:\Users\My_PC\AppData\Local\Programs\Python\Python311\Lib\site-packages\django\db\utils.py", line 91, in __exit__
    raise dj_exc_value.with_traceback(traceback) from exc_value
  File "C:\Users\My_PC\AppData\Local\Programs\Python\Python311\Lib\site-packages\django\db\backends\utils.py", line 89, in _execute
    return self.cursor.execute(sql, params)
           ^^^^^^^^^^^^^^^^^^^^^^^^^^^^^^^^
  File "C:\Users\My_PC\AppData\Local\Programs\Python\Python311\Lib\site-packages\django\db\backends\mysql\base.py", line 75, in execute
    return self.cursor.execute(query, args)
           ^^^^^^^^^^^^^^^^^^^^^^^^^^^^^^^^
  File "C:\Users\My_PC\AppData\Local\Programs\Python\Python311\Lib\site-packages\MySQLdb\cursors.py", line 179, in execute
    res = self._query(mogrified_query)
          ^^^^^^^^^^^^^^^^^^^^^^^^^^^^
  File "C:\Users\My_PC\AppData\Local\Programs\Python\Python311\Lib\site-packages\MySQLdb\cursors.py", line 330, in _query
    db.query(q)
  File "C:\Users\My_PC\AppData\Local\Programs\Python\Python311\Lib\site-packages\MySQLdb\connections.py", line 255, in query
    _mysql.connection.query(self, query)
django.db.utils.ProgrammingError: (1146, "Table 'users.auth_user' doesn't exist")
2023-10-26 09:55:00,696 [ERROR]- Internal Server Error: /accounts/login/
Traceback (most recent call last):
  File "C:\Users\My_PC\AppData\Local\Programs\Python\Python311\Lib\site-packages\django\db\backends\utils.py", line 89, in _execute
    return self.cursor.execute(sql, params)
           ^^^^^^^^^^^^^^^^^^^^^^^^^^^^^^^^
  File "C:\Users\My_PC\AppData\Local\Programs\Python\Python311\Lib\site-packages\django\db\backends\mysql\base.py", line 75, in execute
    return self.cursor.execute(query, args)
           ^^^^^^^^^^^^^^^^^^^^^^^^^^^^^^^^
  File "C:\Users\My_PC\AppData\Local\Programs\Python\Python311\Lib\site-packages\MySQLdb\cursors.py", line 179, in execute
    res = self._query(mogrified_query)
          ^^^^^^^^^^^^^^^^^^^^^^^^^^^^
  File "C:\Users\My_PC\AppData\Local\Programs\Python\Python311\Lib\site-packages\MySQLdb\cursors.py", line 330, in _query
    db.query(q)
  File "C:\Users\My_PC\AppData\Local\Programs\Python\Python311\Lib\site-packages\MySQLdb\connections.py", line 255, in query
    _mysql.connection.query(self, query)
MySQLdb.ProgrammingError: (1146, "Table 'users.auth_user' doesn't exist")

The above exception was the direct cause of the following exception:

Traceback (most recent call last):
  File "C:\Users\My_PC\AppData\Local\Programs\Python\Python311\Lib\site-packages\django\core\handlers\exception.py", line 55, in inner
    response = get_response(request)
               ^^^^^^^^^^^^^^^^^^^^^
  File "C:\Users\My_PC\AppData\Local\Programs\Python\Python311\Lib\site-packages\django\core\handlers\base.py", line 197, in _get_response
    response = wrapped_callback(request, *callback_args, **callback_kwargs)
               ^^^^^^^^^^^^^^^^^^^^^^^^^^^^^^^^^^^^^^^^^^^^^^^^^^^^^^^^^^^^
  File "C:\Users\My_PC\AppData\Local\Programs\Python\Python311\Lib\site-packages\django\views\generic\base.py", line 104, in view
    return self.dispatch(request, *args, **kwargs)
           ^^^^^^^^^^^^^^^^^^^^^^^^^^^^^^^^^^^^^^^
  File "C:\Users\My_PC\AppData\Local\Programs\Python\Python311\Lib\site-packages\django\utils\decorators.py", line 46, in _wrapper
    return bound_method(*args, **kwargs)
           ^^^^^^^^^^^^^^^^^^^^^^^^^^^^^
  File "C:\Users\My_PC\AppData\Local\Programs\Python\Python311\Lib\site-packages\django\views\decorators\debug.py", line 92, in sensitive_post_parameters_wrapper
    return view(request, *args, **kwargs)
           ^^^^^^^^^^^^^^^^^^^^^^^^^^^^^^
  File "C:\Users\My_PC\AppData\Local\Programs\Python\Python311\Lib\site-packages\django\utils\decorators.py", line 46, in _wrapper
    return bound_method(*args, **kwargs)
           ^^^^^^^^^^^^^^^^^^^^^^^^^^^^^
  File "C:\Users\My_PC\AppData\Local\Programs\Python\Python311\Lib\site-packages\django\utils\decorators.py", line 134, in _wrapper_view
    response = view_func(request, *args, **kwargs)
               ^^^^^^^^^^^^^^^^^^^^^^^^^^^^^^^^^^^
  File "C:\Users\My_PC\AppData\Local\Programs\Python\Python311\Lib\site-packages\django\utils\decorators.py", line 46, in _wrapper
    return bound_method(*args, **kwargs)
           ^^^^^^^^^^^^^^^^^^^^^^^^^^^^^
  File "C:\Users\My_PC\AppData\Local\Programs\Python\Python311\Lib\site-packages\django\views\decorators\cache.py", line 62, in _wrapper_view_func
    response = view_func(request, *args, **kwargs)
               ^^^^^^^^^^^^^^^^^^^^^^^^^^^^^^^^^^^
  File "C:\Users\My_PC\AppData\Local\Programs\Python\Python311\Lib\site-packages\django\contrib\auth\views.py", line 90, in dispatch
    return super().dispatch(request, *args, **kwargs)
           ^^^^^^^^^^^^^^^^^^^^^^^^^^^^^^^^^^^^^^^^^^
  File "C:\Users\My_PC\AppData\Local\Programs\Python\Python311\Lib\site-packages\django\views\generic\base.py", line 143, in dispatch
    return handler(request, *args, **kwargs)
           ^^^^^^^^^^^^^^^^^^^^^^^^^^^^^^^^^
  File "C:\Users\My_PC\AppData\Local\Programs\Python\Python311\Lib\site-packages\django\views\generic\edit.py", line 152, in post
    if form.is_valid():
       ^^^^^^^^^^^^^^^
  File "C:\Users\My_PC\AppData\Local\Programs\Python\Python311\Lib\site-packages\django\forms\forms.py", line 201, in is_valid
    return self.is_bound and not self.errors
                                 ^^^^^^^^^^^
  File "C:\Users\My_PC\AppData\Local\Programs\Python\Python311\Lib\site-packages\django\forms\forms.py", line 196, in errors
    self.full_clean()
  File "C:\Users\My_PC\AppData\Local\Programs\Python\Python311\Lib\site-packages\django\forms\forms.py", line 434, in full_clean
    self._clean_form()
  File "C:\Users\My_PC\AppData\Local\Programs\Python\Python311\Lib\site-packages\django\forms\forms.py", line 455, in _clean_form
    cleaned_data = self.clean()
                   ^^^^^^^^^^^^
  File "C:\Users\My_PC\AppData\Local\Programs\Python\Python311\Lib\site-packages\django\contrib\auth\forms.py", line 242, in clean
    self.user_cache = authenticate(
                      ^^^^^^^^^^^^^
  File "C:\Users\My_PC\AppData\Local\Programs\Python\Python311\Lib\site-packages\django\views\decorators\debug.py", line 42, in sensitive_variables_wrapper
    return func(*func_args, **func_kwargs)
           ^^^^^^^^^^^^^^^^^^^^^^^^^^^^^^^
  File "C:\Users\My_PC\AppData\Local\Programs\Python\Python311\Lib\site-packages\django\contrib\auth\__init__.py", line 77, in authenticate
    user = backend.authenticate(request, **credentials)
           ^^^^^^^^^^^^^^^^^^^^^^^^^^^^^^^^^^^^^^^^^^^^
  File "C:\Users\My_PC\AppData\Local\Programs\Python\Python311\Lib\site-packages\django\contrib\auth\backends.py", line 46, in authenticate
    user = UserModel._default_manager.get_by_natural_key(username)
           ^^^^^^^^^^^^^^^^^^^^^^^^^^^^^^^^^^^^^^^^^^^^^^^^^^^^^^^
  File "C:\Users\My_PC\AppData\Local\Programs\Python\Python311\Lib\site-packages\django\contrib\auth\base_user.py", line 54, in get_by_natural_key
    return self.get(**{self.model.USERNAME_FIELD: username})
           ^^^^^^^^^^^^^^^^^^^^^^^^^^^^^^^^^^^^^^^^^^^^^^^^^
  File "C:\Users\My_PC\AppData\Local\Programs\Python\Python311\Lib\site-packages\django\db\models\manager.py", line 87, in manager_method
    return getattr(self.get_queryset(), name)(*args, **kwargs)
           ^^^^^^^^^^^^^^^^^^^^^^^^^^^^^^^^^^^^^^^^^^^^^^^^^^^
  File "C:\Users\My_PC\AppData\Local\Programs\Python\Python311\Lib\site-packages\django\db\models\query.py", line 633, in get
    num = len(clone)
          ^^^^^^^^^^
  File "C:\Users\My_PC\AppData\Local\Programs\Python\Python311\Lib\site-packages\django\db\models\query.py", line 380, in __len__
    self._fetch_all()
  File "C:\Users\My_PC\AppData\Local\Programs\Python\Python311\Lib\site-packages\django\db\models\query.py", line 1881, in _fetch_all
    self._result_cache = list(self._iterable_class(self))
                         ^^^^^^^^^^^^^^^^^^^^^^^^^^^^^^^^
  File "C:\Users\My_PC\AppData\Local\Programs\Python\Python311\Lib\site-packages\django\db\models\query.py", line 91, in __iter__
    results = compiler.execute_sql(
              ^^^^^^^^^^^^^^^^^^^^^
  File "C:\Users\My_PC\AppData\Local\Programs\Python\Python311\Lib\site-packages\django\db\models\sql\compiler.py", line 1562, in execute_sql
    cursor.execute(sql, params)
  File "C:\Users\My_PC\AppData\Local\Programs\Python\Python311\Lib\site-packages\django\db\backends\utils.py", line 102, in execute
    return super().execute(sql, params)
           ^^^^^^^^^^^^^^^^^^^^^^^^^^^^
  File "C:\Users\My_PC\AppData\Local\Programs\Python\Python311\Lib\site-packages\django\db\backends\utils.py", line 67, in execute
    return self._execute_with_wrappers(
           ^^^^^^^^^^^^^^^^^^^^^^^^^^^^
  File "C:\Users\My_PC\AppData\Local\Programs\Python\Python311\Lib\site-packages\django\db\backends\utils.py", line 80, in _execute_with_wrappers
    return executor(sql, params, many, context)
           ^^^^^^^^^^^^^^^^^^^^^^^^^^^^^^^^^^^^
  File "C:\Users\My_PC\AppData\Local\Programs\Python\Python311\Lib\site-packages\django\db\backends\utils.py", line 84, in _execute
    with self.db.wrap_database_errors:
  File "C:\Users\My_PC\AppData\Local\Programs\Python\Python311\Lib\site-packages\django\db\utils.py", line 91, in __exit__
    raise dj_exc_value.with_traceback(traceback) from exc_value
  File "C:\Users\My_PC\AppData\Local\Programs\Python\Python311\Lib\site-packages\django\db\backends\utils.py", line 89, in _execute
    return self.cursor.execute(sql, params)
           ^^^^^^^^^^^^^^^^^^^^^^^^^^^^^^^^
  File "C:\Users\My_PC\AppData\Local\Programs\Python\Python311\Lib\site-packages\django\db\backends\mysql\base.py", line 75, in execute
    return self.cursor.execute(query, args)
           ^^^^^^^^^^^^^^^^^^^^^^^^^^^^^^^^
  File "C:\Users\My_PC\AppData\Local\Programs\Python\Python311\Lib\site-packages\MySQLdb\cursors.py", line 179, in execute
    res = self._query(mogrified_query)
          ^^^^^^^^^^^^^^^^^^^^^^^^^^^^
  File "C:\Users\My_PC\AppData\Local\Programs\Python\Python311\Lib\site-packages\MySQLdb\cursors.py", line 330, in _query
    db.query(q)
  File "C:\Users\My_PC\AppData\Local\Programs\Python\Python311\Lib\site-packages\MySQLdb\connections.py", line 255, in query
    _mysql.connection.query(self, query)
django.db.utils.ProgrammingError: (1146, "Table 'users.auth_user' doesn't exist")
2023-10-26 09:56:00,302 [ERROR]- Internal Server Error: /accounts/login/
Traceback (most recent call last):
  File "C:\Users\My_PC\AppData\Local\Programs\Python\Python311\Lib\site-packages\django\db\backends\utils.py", line 89, in _execute
    return self.cursor.execute(sql, params)
           ^^^^^^^^^^^^^^^^^^^^^^^^^^^^^^^^
  File "C:\Users\My_PC\AppData\Local\Programs\Python\Python311\Lib\site-packages\django\db\backends\mysql\base.py", line 75, in execute
    return self.cursor.execute(query, args)
           ^^^^^^^^^^^^^^^^^^^^^^^^^^^^^^^^
  File "C:\Users\My_PC\AppData\Local\Programs\Python\Python311\Lib\site-packages\MySQLdb\cursors.py", line 179, in execute
    res = self._query(mogrified_query)
          ^^^^^^^^^^^^^^^^^^^^^^^^^^^^
  File "C:\Users\My_PC\AppData\Local\Programs\Python\Python311\Lib\site-packages\MySQLdb\cursors.py", line 330, in _query
    db.query(q)
  File "C:\Users\My_PC\AppData\Local\Programs\Python\Python311\Lib\site-packages\MySQLdb\connections.py", line 255, in query
    _mysql.connection.query(self, query)
MySQLdb.ProgrammingError: (1146, "Table 'users.auth_user' doesn't exist")

The above exception was the direct cause of the following exception:

Traceback (most recent call last):
  File "C:\Users\My_PC\AppData\Local\Programs\Python\Python311\Lib\site-packages\django\core\handlers\exception.py", line 55, in inner
    response = get_response(request)
               ^^^^^^^^^^^^^^^^^^^^^
  File "C:\Users\My_PC\AppData\Local\Programs\Python\Python311\Lib\site-packages\django\core\handlers\base.py", line 197, in _get_response
    response = wrapped_callback(request, *callback_args, **callback_kwargs)
               ^^^^^^^^^^^^^^^^^^^^^^^^^^^^^^^^^^^^^^^^^^^^^^^^^^^^^^^^^^^^
  File "C:\Users\My_PC\AppData\Local\Programs\Python\Python311\Lib\site-packages\django\views\generic\base.py", line 104, in view
    return self.dispatch(request, *args, **kwargs)
           ^^^^^^^^^^^^^^^^^^^^^^^^^^^^^^^^^^^^^^^
  File "C:\Users\My_PC\AppData\Local\Programs\Python\Python311\Lib\site-packages\django\utils\decorators.py", line 46, in _wrapper
    return bound_method(*args, **kwargs)
           ^^^^^^^^^^^^^^^^^^^^^^^^^^^^^
  File "C:\Users\My_PC\AppData\Local\Programs\Python\Python311\Lib\site-packages\django\views\decorators\debug.py", line 92, in sensitive_post_parameters_wrapper
    return view(request, *args, **kwargs)
           ^^^^^^^^^^^^^^^^^^^^^^^^^^^^^^
  File "C:\Users\My_PC\AppData\Local\Programs\Python\Python311\Lib\site-packages\django\utils\decorators.py", line 46, in _wrapper
    return bound_method(*args, **kwargs)
           ^^^^^^^^^^^^^^^^^^^^^^^^^^^^^
  File "C:\Users\My_PC\AppData\Local\Programs\Python\Python311\Lib\site-packages\django\utils\decorators.py", line 134, in _wrapper_view
    response = view_func(request, *args, **kwargs)
               ^^^^^^^^^^^^^^^^^^^^^^^^^^^^^^^^^^^
  File "C:\Users\My_PC\AppData\Local\Programs\Python\Python311\Lib\site-packages\django\utils\decorators.py", line 46, in _wrapper
    return bound_method(*args, **kwargs)
           ^^^^^^^^^^^^^^^^^^^^^^^^^^^^^
  File "C:\Users\My_PC\AppData\Local\Programs\Python\Python311\Lib\site-packages\django\views\decorators\cache.py", line 62, in _wrapper_view_func
    response = view_func(request, *args, **kwargs)
               ^^^^^^^^^^^^^^^^^^^^^^^^^^^^^^^^^^^
  File "C:\Users\My_PC\AppData\Local\Programs\Python\Python311\Lib\site-packages\django\contrib\auth\views.py", line 90, in dispatch
    return super().dispatch(request, *args, **kwargs)
           ^^^^^^^^^^^^^^^^^^^^^^^^^^^^^^^^^^^^^^^^^^
  File "C:\Users\My_PC\AppData\Local\Programs\Python\Python311\Lib\site-packages\django\views\generic\base.py", line 143, in dispatch
    return handler(request, *args, **kwargs)
           ^^^^^^^^^^^^^^^^^^^^^^^^^^^^^^^^^
  File "C:\Users\My_PC\AppData\Local\Programs\Python\Python311\Lib\site-packages\django\views\generic\edit.py", line 152, in post
    if form.is_valid():
       ^^^^^^^^^^^^^^^
  File "C:\Users\My_PC\AppData\Local\Programs\Python\Python311\Lib\site-packages\django\forms\forms.py", line 201, in is_valid
    return self.is_bound and not self.errors
                                 ^^^^^^^^^^^
  File "C:\Users\My_PC\AppData\Local\Programs\Python\Python311\Lib\site-packages\django\forms\forms.py", line 196, in errors
    self.full_clean()
  File "C:\Users\My_PC\AppData\Local\Programs\Python\Python311\Lib\site-packages\django\forms\forms.py", line 434, in full_clean
    self._clean_form()
  File "C:\Users\My_PC\AppData\Local\Programs\Python\Python311\Lib\site-packages\django\forms\forms.py", line 455, in _clean_form
    cleaned_data = self.clean()
                   ^^^^^^^^^^^^
  File "C:\Users\My_PC\AppData\Local\Programs\Python\Python311\Lib\site-packages\django\contrib\auth\forms.py", line 242, in clean
    self.user_cache = authenticate(
                      ^^^^^^^^^^^^^
  File "C:\Users\My_PC\AppData\Local\Programs\Python\Python311\Lib\site-packages\django\views\decorators\debug.py", line 42, in sensitive_variables_wrapper
    return func(*func_args, **func_kwargs)
           ^^^^^^^^^^^^^^^^^^^^^^^^^^^^^^^
  File "C:\Users\My_PC\AppData\Local\Programs\Python\Python311\Lib\site-packages\django\contrib\auth\__init__.py", line 77, in authenticate
    user = backend.authenticate(request, **credentials)
           ^^^^^^^^^^^^^^^^^^^^^^^^^^^^^^^^^^^^^^^^^^^^
  File "C:\Users\My_PC\AppData\Local\Programs\Python\Python311\Lib\site-packages\django\contrib\auth\backends.py", line 46, in authenticate
    user = UserModel._default_manager.get_by_natural_key(username)
           ^^^^^^^^^^^^^^^^^^^^^^^^^^^^^^^^^^^^^^^^^^^^^^^^^^^^^^^
  File "C:\Users\My_PC\AppData\Local\Programs\Python\Python311\Lib\site-packages\django\contrib\auth\base_user.py", line 54, in get_by_natural_key
    return self.get(**{self.model.USERNAME_FIELD: username})
           ^^^^^^^^^^^^^^^^^^^^^^^^^^^^^^^^^^^^^^^^^^^^^^^^^
  File "C:\Users\My_PC\AppData\Local\Programs\Python\Python311\Lib\site-packages\django\db\models\manager.py", line 87, in manager_method
    return getattr(self.get_queryset(), name)(*args, **kwargs)
           ^^^^^^^^^^^^^^^^^^^^^^^^^^^^^^^^^^^^^^^^^^^^^^^^^^^
  File "C:\Users\My_PC\AppData\Local\Programs\Python\Python311\Lib\site-packages\django\db\models\query.py", line 633, in get
    num = len(clone)
          ^^^^^^^^^^
  File "C:\Users\My_PC\AppData\Local\Programs\Python\Python311\Lib\site-packages\django\db\models\query.py", line 380, in __len__
    self._fetch_all()
  File "C:\Users\My_PC\AppData\Local\Programs\Python\Python311\Lib\site-packages\django\db\models\query.py", line 1881, in _fetch_all
    self._result_cache = list(self._iterable_class(self))
                         ^^^^^^^^^^^^^^^^^^^^^^^^^^^^^^^^
  File "C:\Users\My_PC\AppData\Local\Programs\Python\Python311\Lib\site-packages\django\db\models\query.py", line 91, in __iter__
    results = compiler.execute_sql(
              ^^^^^^^^^^^^^^^^^^^^^
  File "C:\Users\My_PC\AppData\Local\Programs\Python\Python311\Lib\site-packages\django\db\models\sql\compiler.py", line 1562, in execute_sql
    cursor.execute(sql, params)
  File "C:\Users\My_PC\AppData\Local\Programs\Python\Python311\Lib\site-packages\django\db\backends\utils.py", line 102, in execute
    return super().execute(sql, params)
           ^^^^^^^^^^^^^^^^^^^^^^^^^^^^
  File "C:\Users\My_PC\AppData\Local\Programs\Python\Python311\Lib\site-packages\django\db\backends\utils.py", line 67, in execute
    return self._execute_with_wrappers(
           ^^^^^^^^^^^^^^^^^^^^^^^^^^^^
  File "C:\Users\My_PC\AppData\Local\Programs\Python\Python311\Lib\site-packages\django\db\backends\utils.py", line 80, in _execute_with_wrappers
    return executor(sql, params, many, context)
           ^^^^^^^^^^^^^^^^^^^^^^^^^^^^^^^^^^^^
  File "C:\Users\My_PC\AppData\Local\Programs\Python\Python311\Lib\site-packages\django\db\backends\utils.py", line 84, in _execute
    with self.db.wrap_database_errors:
  File "C:\Users\My_PC\AppData\Local\Programs\Python\Python311\Lib\site-packages\django\db\utils.py", line 91, in __exit__
    raise dj_exc_value.with_traceback(traceback) from exc_value
  File "C:\Users\My_PC\AppData\Local\Programs\Python\Python311\Lib\site-packages\django\db\backends\utils.py", line 89, in _execute
    return self.cursor.execute(sql, params)
           ^^^^^^^^^^^^^^^^^^^^^^^^^^^^^^^^
  File "C:\Users\My_PC\AppData\Local\Programs\Python\Python311\Lib\site-packages\django\db\backends\mysql\base.py", line 75, in execute
    return self.cursor.execute(query, args)
           ^^^^^^^^^^^^^^^^^^^^^^^^^^^^^^^^
  File "C:\Users\My_PC\AppData\Local\Programs\Python\Python311\Lib\site-packages\MySQLdb\cursors.py", line 179, in execute
    res = self._query(mogrified_query)
          ^^^^^^^^^^^^^^^^^^^^^^^^^^^^
  File "C:\Users\My_PC\AppData\Local\Programs\Python\Python311\Lib\site-packages\MySQLdb\cursors.py", line 330, in _query
    db.query(q)
  File "C:\Users\My_PC\AppData\Local\Programs\Python\Python311\Lib\site-packages\MySQLdb\connections.py", line 255, in query
    _mysql.connection.query(self, query)
django.db.utils.ProgrammingError: (1146, "Table 'users.auth_user' doesn't exist")
2023-10-26 09:59:06,312 [ERROR]- Internal Server Error: /accounts/login/
Traceback (most recent call last):
  File "C:\Users\My_PC\AppData\Local\Programs\Python\Python311\Lib\site-packages\django\db\backends\utils.py", line 89, in _execute
    return self.cursor.execute(sql, params)
           ^^^^^^^^^^^^^^^^^^^^^^^^^^^^^^^^
  File "C:\Users\My_PC\AppData\Local\Programs\Python\Python311\Lib\site-packages\django\db\backends\mysql\base.py", line 75, in execute
    return self.cursor.execute(query, args)
           ^^^^^^^^^^^^^^^^^^^^^^^^^^^^^^^^
  File "C:\Users\My_PC\AppData\Local\Programs\Python\Python311\Lib\site-packages\MySQLdb\cursors.py", line 179, in execute
    res = self._query(mogrified_query)
          ^^^^^^^^^^^^^^^^^^^^^^^^^^^^
  File "C:\Users\My_PC\AppData\Local\Programs\Python\Python311\Lib\site-packages\MySQLdb\cursors.py", line 330, in _query
    db.query(q)
  File "C:\Users\My_PC\AppData\Local\Programs\Python\Python311\Lib\site-packages\MySQLdb\connections.py", line 255, in query
    _mysql.connection.query(self, query)
MySQLdb.ProgrammingError: (1146, "Table 'users.auth_user' doesn't exist")

The above exception was the direct cause of the following exception:

Traceback (most recent call last):
  File "C:\Users\My_PC\AppData\Local\Programs\Python\Python311\Lib\site-packages\django\core\handlers\exception.py", line 55, in inner
    response = get_response(request)
               ^^^^^^^^^^^^^^^^^^^^^
  File "C:\Users\My_PC\AppData\Local\Programs\Python\Python311\Lib\site-packages\django\core\handlers\base.py", line 197, in _get_response
    response = wrapped_callback(request, *callback_args, **callback_kwargs)
               ^^^^^^^^^^^^^^^^^^^^^^^^^^^^^^^^^^^^^^^^^^^^^^^^^^^^^^^^^^^^
  File "C:\Users\My_PC\AppData\Local\Programs\Python\Python311\Lib\site-packages\django\views\generic\base.py", line 104, in view
    return self.dispatch(request, *args, **kwargs)
           ^^^^^^^^^^^^^^^^^^^^^^^^^^^^^^^^^^^^^^^
  File "C:\Users\My_PC\AppData\Local\Programs\Python\Python311\Lib\site-packages\django\utils\decorators.py", line 46, in _wrapper
    return bound_method(*args, **kwargs)
           ^^^^^^^^^^^^^^^^^^^^^^^^^^^^^
  File "C:\Users\My_PC\AppData\Local\Programs\Python\Python311\Lib\site-packages\django\views\decorators\debug.py", line 92, in sensitive_post_parameters_wrapper
    return view(request, *args, **kwargs)
           ^^^^^^^^^^^^^^^^^^^^^^^^^^^^^^
  File "C:\Users\My_PC\AppData\Local\Programs\Python\Python311\Lib\site-packages\django\utils\decorators.py", line 46, in _wrapper
    return bound_method(*args, **kwargs)
           ^^^^^^^^^^^^^^^^^^^^^^^^^^^^^
  File "C:\Users\My_PC\AppData\Local\Programs\Python\Python311\Lib\site-packages\django\utils\decorators.py", line 134, in _wrapper_view
    response = view_func(request, *args, **kwargs)
               ^^^^^^^^^^^^^^^^^^^^^^^^^^^^^^^^^^^
  File "C:\Users\My_PC\AppData\Local\Programs\Python\Python311\Lib\site-packages\django\utils\decorators.py", line 46, in _wrapper
    return bound_method(*args, **kwargs)
           ^^^^^^^^^^^^^^^^^^^^^^^^^^^^^
  File "C:\Users\My_PC\AppData\Local\Programs\Python\Python311\Lib\site-packages\django\views\decorators\cache.py", line 62, in _wrapper_view_func
    response = view_func(request, *args, **kwargs)
               ^^^^^^^^^^^^^^^^^^^^^^^^^^^^^^^^^^^
  File "C:\Users\My_PC\AppData\Local\Programs\Python\Python311\Lib\site-packages\django\contrib\auth\views.py", line 90, in dispatch
    return super().dispatch(request, *args, **kwargs)
           ^^^^^^^^^^^^^^^^^^^^^^^^^^^^^^^^^^^^^^^^^^
  File "C:\Users\My_PC\AppData\Local\Programs\Python\Python311\Lib\site-packages\django\views\generic\base.py", line 143, in dispatch
    return handler(request, *args, **kwargs)
           ^^^^^^^^^^^^^^^^^^^^^^^^^^^^^^^^^
  File "C:\Users\My_PC\AppData\Local\Programs\Python\Python311\Lib\site-packages\django\views\generic\edit.py", line 152, in post
    if form.is_valid():
       ^^^^^^^^^^^^^^^
  File "C:\Users\My_PC\AppData\Local\Programs\Python\Python311\Lib\site-packages\django\forms\forms.py", line 201, in is_valid
    return self.is_bound and not self.errors
                                 ^^^^^^^^^^^
  File "C:\Users\My_PC\AppData\Local\Programs\Python\Python311\Lib\site-packages\django\forms\forms.py", line 196, in errors
    self.full_clean()
  File "C:\Users\My_PC\AppData\Local\Programs\Python\Python311\Lib\site-packages\django\forms\forms.py", line 434, in full_clean
    self._clean_form()
  File "C:\Users\My_PC\AppData\Local\Programs\Python\Python311\Lib\site-packages\django\forms\forms.py", line 455, in _clean_form
    cleaned_data = self.clean()
                   ^^^^^^^^^^^^
  File "C:\Users\My_PC\AppData\Local\Programs\Python\Python311\Lib\site-packages\django\contrib\auth\forms.py", line 242, in clean
    self.user_cache = authenticate(
                      ^^^^^^^^^^^^^
  File "C:\Users\My_PC\AppData\Local\Programs\Python\Python311\Lib\site-packages\django\views\decorators\debug.py", line 42, in sensitive_variables_wrapper
    return func(*func_args, **func_kwargs)
           ^^^^^^^^^^^^^^^^^^^^^^^^^^^^^^^
  File "C:\Users\My_PC\AppData\Local\Programs\Python\Python311\Lib\site-packages\django\contrib\auth\__init__.py", line 77, in authenticate
    user = backend.authenticate(request, **credentials)
           ^^^^^^^^^^^^^^^^^^^^^^^^^^^^^^^^^^^^^^^^^^^^
  File "C:\Users\My_PC\AppData\Local\Programs\Python\Python311\Lib\site-packages\django\contrib\auth\backends.py", line 46, in authenticate
    user = UserModel._default_manager.get_by_natural_key(username)
           ^^^^^^^^^^^^^^^^^^^^^^^^^^^^^^^^^^^^^^^^^^^^^^^^^^^^^^^
  File "C:\Users\My_PC\AppData\Local\Programs\Python\Python311\Lib\site-packages\django\contrib\auth\base_user.py", line 54, in get_by_natural_key
    return self.get(**{self.model.USERNAME_FIELD: username})
           ^^^^^^^^^^^^^^^^^^^^^^^^^^^^^^^^^^^^^^^^^^^^^^^^^
  File "C:\Users\My_PC\AppData\Local\Programs\Python\Python311\Lib\site-packages\django\db\models\manager.py", line 87, in manager_method
    return getattr(self.get_queryset(), name)(*args, **kwargs)
           ^^^^^^^^^^^^^^^^^^^^^^^^^^^^^^^^^^^^^^^^^^^^^^^^^^^
  File "C:\Users\My_PC\AppData\Local\Programs\Python\Python311\Lib\site-packages\django\db\models\query.py", line 633, in get
    num = len(clone)
          ^^^^^^^^^^
  File "C:\Users\My_PC\AppData\Local\Programs\Python\Python311\Lib\site-packages\django\db\models\query.py", line 380, in __len__
    self._fetch_all()
  File "C:\Users\My_PC\AppData\Local\Programs\Python\Python311\Lib\site-packages\django\db\models\query.py", line 1881, in _fetch_all
    self._result_cache = list(self._iterable_class(self))
                         ^^^^^^^^^^^^^^^^^^^^^^^^^^^^^^^^
  File "C:\Users\My_PC\AppData\Local\Programs\Python\Python311\Lib\site-packages\django\db\models\query.py", line 91, in __iter__
    results = compiler.execute_sql(
              ^^^^^^^^^^^^^^^^^^^^^
  File "C:\Users\My_PC\AppData\Local\Programs\Python\Python311\Lib\site-packages\django\db\models\sql\compiler.py", line 1562, in execute_sql
    cursor.execute(sql, params)
  File "C:\Users\My_PC\AppData\Local\Programs\Python\Python311\Lib\site-packages\django\db\backends\utils.py", line 102, in execute
    return super().execute(sql, params)
           ^^^^^^^^^^^^^^^^^^^^^^^^^^^^
  File "C:\Users\My_PC\AppData\Local\Programs\Python\Python311\Lib\site-packages\django\db\backends\utils.py", line 67, in execute
    return self._execute_with_wrappers(
           ^^^^^^^^^^^^^^^^^^^^^^^^^^^^
  File "C:\Users\My_PC\AppData\Local\Programs\Python\Python311\Lib\site-packages\django\db\backends\utils.py", line 80, in _execute_with_wrappers
    return executor(sql, params, many, context)
           ^^^^^^^^^^^^^^^^^^^^^^^^^^^^^^^^^^^^
  File "C:\Users\My_PC\AppData\Local\Programs\Python\Python311\Lib\site-packages\django\db\backends\utils.py", line 84, in _execute
    with self.db.wrap_database_errors:
  File "C:\Users\My_PC\AppData\Local\Programs\Python\Python311\Lib\site-packages\django\db\utils.py", line 91, in __exit__
    raise dj_exc_value.with_traceback(traceback) from exc_value
  File "C:\Users\My_PC\AppData\Local\Programs\Python\Python311\Lib\site-packages\django\db\backends\utils.py", line 89, in _execute
    return self.cursor.execute(sql, params)
           ^^^^^^^^^^^^^^^^^^^^^^^^^^^^^^^^
  File "C:\Users\My_PC\AppData\Local\Programs\Python\Python311\Lib\site-packages\django\db\backends\mysql\base.py", line 75, in execute
    return self.cursor.execute(query, args)
           ^^^^^^^^^^^^^^^^^^^^^^^^^^^^^^^^
  File "C:\Users\My_PC\AppData\Local\Programs\Python\Python311\Lib\site-packages\MySQLdb\cursors.py", line 179, in execute
    res = self._query(mogrified_query)
          ^^^^^^^^^^^^^^^^^^^^^^^^^^^^
  File "C:\Users\My_PC\AppData\Local\Programs\Python\Python311\Lib\site-packages\MySQLdb\cursors.py", line 330, in _query
    db.query(q)
  File "C:\Users\My_PC\AppData\Local\Programs\Python\Python311\Lib\site-packages\MySQLdb\connections.py", line 255, in query
    _mysql.connection.query(self, query)
django.db.utils.ProgrammingError: (1146, "Table 'users.auth_user' doesn't exist")
2023-10-26 12:57:52,848 [ERROR]- Internal Server Error: /
Traceback (most recent call last):
  File "C:\Users\My_PC\AppData\Local\Programs\Python\Python311\Lib\site-packages\django\core\handlers\exception.py", line 55, in inner
    response = get_response(request)
               ^^^^^^^^^^^^^^^^^^^^^
  File "C:\Users\My_PC\AppData\Local\Programs\Python\Python311\Lib\site-packages\django\core\handlers\base.py", line 197, in _get_response
    response = wrapped_callback(request, *callback_args, **callback_kwargs)
               ^^^^^^^^^^^^^^^^^^^^^^^^^^^^^^^^^^^^^^^^^^^^^^^^^^^^^^^^^^^^
  File "C:\Users\My_PC\AppData\Local\Programs\Python\Python311\Lib\site-packages\django\views\generic\base.py", line 104, in view
    return self.dispatch(request, *args, **kwargs)
           ^^^^^^^^^^^^^^^^^^^^^^^^^^^^^^^^^^^^^^^
  File "C:\Users\My_PC\AppData\Local\Programs\Python\Python311\Lib\site-packages\django\views\generic\base.py", line 143, in dispatch
    return handler(request, *args, **kwargs)
           ^^^^^^^^^^^^^^^^^^^^^^^^^^^^^^^^^
  File "C:\Users\My_PC\Desktop\nosedive-master\main\views.py", line 49, in post
    current_rating = rated_user.profile.rating
                     ^^^^^^^^^^^^^^^^^^
  File "C:\Users\My_PC\AppData\Local\Programs\Python\Python311\Lib\site-packages\django\db\models\fields\related_descriptors.py", line 492, in __get__
    raise self.RelatedObjectDoesNotExist(
django.contrib.auth.models.User.profile.RelatedObjectDoesNotExist: User has no profile.
2023-10-26 12:58:26,232 [ERROR]- Internal Server Error: /
Traceback (most recent call last):
  File "C:\Users\My_PC\AppData\Local\Programs\Python\Python311\Lib\site-packages\django\core\handlers\exception.py", line 55, in inner
    response = get_response(request)
               ^^^^^^^^^^^^^^^^^^^^^
  File "C:\Users\My_PC\AppData\Local\Programs\Python\Python311\Lib\site-packages\django\core\handlers\base.py", line 197, in _get_response
    response = wrapped_callback(request, *callback_args, **callback_kwargs)
               ^^^^^^^^^^^^^^^^^^^^^^^^^^^^^^^^^^^^^^^^^^^^^^^^^^^^^^^^^^^^
  File "C:\Users\My_PC\AppData\Local\Programs\Python\Python311\Lib\site-packages\django\views\generic\base.py", line 104, in view
    return self.dispatch(request, *args, **kwargs)
           ^^^^^^^^^^^^^^^^^^^^^^^^^^^^^^^^^^^^^^^
  File "C:\Users\My_PC\AppData\Local\Programs\Python\Python311\Lib\site-packages\django\views\generic\base.py", line 143, in dispatch
    return handler(request, *args, **kwargs)
           ^^^^^^^^^^^^^^^^^^^^^^^^^^^^^^^^^
  File "C:\Users\My_PC\Desktop\nosedive-master\main\views.py", line 49, in post
    current_rating = rated_user.profile.rating
                     ^^^^^^^^^^^^^^^^^^
  File "C:\Users\My_PC\AppData\Local\Programs\Python\Python311\Lib\site-packages\django\db\models\fields\related_descriptors.py", line 492, in __get__
    raise self.RelatedObjectDoesNotExist(
django.contrib.auth.models.User.profile.RelatedObjectDoesNotExist: User has no profile.
2023-10-26 13:58:27,715 [WARNING]- Not Found: /iamages.png
2023-10-26 13:58:30,574 [WARNING]- Not Found: /iamages.png
2023-10-26 13:58:45,247 [WARNING]- Not Found: /iamages.png
2023-10-26 13:58:52,545 [WARNING]- Not Found: /iamages.png
2023-10-26 13:59:09,448 [WARNING]- Not Found: /images.png
2023-10-26 13:59:10,445 [WARNING]- Not Found: /images.png
2023-10-26 13:59:10,824 [WARNING]- Not Found: /images.png
2023-10-26 13:59:11,204 [WARNING]- Not Found: /images.png
2023-10-26 13:59:33,630 [WARNING]- Not Found: /images.png
2023-10-26 13:59:34,120 [WARNING]- Not Found: /images.png
2023-10-26 13:59:34,725 [WARNING]- Not Found: /images.png
2023-10-26 13:59:42,803 [WARNING]- Not Found: /images.png
2023-10-26 13:59:43,430 [WARNING]- Not Found: /images.png
2023-10-26 14:01:00,520 [WARNING]- Not Found: /images.png
2023-10-26 14:01:00,997 [WARNING]- Not Found: /images.png
2023-10-26 14:05:54,377 [WARNING]- Not Found: /templates/images.png
2023-10-26 14:05:55,300 [WARNING]- Not Found: /templates/images.png
2023-10-26 14:05:58,903 [WARNING]- Not Found: /templates/images.png
2023-10-26 14:06:39,119 [WARNING]- Not Found: /templates/images.png
2023-10-26 14:06:50,618 [WARNING]- Not Found: /templates/images.png
2023-10-26 14:07:16,477 [WARNING]- Not Found: /templates/images.png
2023-10-26 15:20:51,353 [WARNING]- Not Found: /uploadDile
2023-10-26 15:23:46,120 [WARNING]- Not Found: /upload.html
2023-10-26 15:25:20,435 [WARNING]- Not Found: /upload.html
2023-10-26 15:25:44,822 [WARNING]- Not Found: /upload.html
2023-10-26 15:25:56,422 [WARNING]- Not Found: /upload.html
2023-10-26 15:25:59,172 [WARNING]- Not Found: /uploadFile
2023-10-26 15:37:21,272 [WARNING]- Not Found: /upload.html
2023-10-26 15:48:29,094 [WARNING]- Not Found: /uploadFile
2023-10-26 15:53:30,700 [WARNING]- Not Found: /uploadFile
2023-10-26 15:55:58,034 [WARNING]- Not Found: /uploadFile/result
2023-10-26 15:57:15,907 [WARNING]- Not Found: /uploadFile
2023-10-26 15:57:29,642 [WARNING]- Not Found: /uploadFile
2023-10-26 15:57:41,424 [ERROR]- Internal Server Error: /upload_file
Traceback (most recent call last):
  File "C:\Users\My_PC\AppData\Local\Programs\Python\Python311\Lib\site-packages\django\core\handlers\exception.py", line 55, in inner
    response = get_response(request)
               ^^^^^^^^^^^^^^^^^^^^^
  File "C:\Users\My_PC\AppData\Local\Programs\Python\Python311\Lib\site-packages\django\utils\deprecation.py", line 136, in __call__
    response = self.process_response(request, response)
               ^^^^^^^^^^^^^^^^^^^^^^^^^^^^^^^^^^^^^^^^
  File "C:\Users\My_PC\AppData\Local\Programs\Python\Python311\Lib\site-packages\django\middleware\common.py", line 108, in process_response
    return self.response_redirect_class(self.get_full_path_with_slash(request))
                                        ^^^^^^^^^^^^^^^^^^^^^^^^^^^^^^^^^^^^^^
  File "C:\Users\My_PC\AppData\Local\Programs\Python\Python311\Lib\site-packages\django\middleware\common.py", line 87, in get_full_path_with_slash
    raise RuntimeError(
RuntimeError: You called this URL via POST, but the URL doesn't end in a slash and you have APPEND_SLASH set. Django can't redirect to the slash URL while maintaining POST data. Change your form to point to 0.0.0.0:8222/upload_file/ (note the trailing slash), or set APPEND_SLASH=False in your Django settings.
2023-10-26 16:12:03,418 [WARNING]- Not Found: /uploadFile
2023-10-26 16:12:46,622 [WARNING]- Not Found: /uploadFile
2023-10-26 16:12:51,951 [WARNING]- Not Found: /uploadFile
2023-10-26 16:13:14,208 [WARNING]- Not Found: /uploadFile
2023-10-26 16:13:14,969 [WARNING]- Not Found: /uploadFile
2023-10-26 17:39:00,742 [WARNING]- Not Found: /favicon.ico
2023-10-26 18:27:50,393 [WARNING]- Not Found: /favicon.ico
2023-10-27 15:51:40,639 [WARNING]- Not Found: /favicon.ico
2023-10-27 16:09:06,321 [ERROR]- Internal Server Error: /admin/login/
Traceback (most recent call last):
  File "C:\Users\My_PC\AppData\Local\Programs\Python\Python311\Lib\site-packages\django\core\handlers\exception.py", line 55, in inner
    response = get_response(request)
               ^^^^^^^^^^^^^^^^^^^^^
  File "C:\Users\My_PC\AppData\Local\Programs\Python\Python311\Lib\site-packages\django\core\handlers\base.py", line 197, in _get_response
    response = wrapped_callback(request, *callback_args, **callback_kwargs)
               ^^^^^^^^^^^^^^^^^^^^^^^^^^^^^^^^^^^^^^^^^^^^^^^^^^^^^^^^^^^^
  File "C:\Users\My_PC\AppData\Local\Programs\Python\Python311\Lib\site-packages\django\utils\decorators.py", line 46, in _wrapper
    return bound_method(*args, **kwargs)
           ^^^^^^^^^^^^^^^^^^^^^^^^^^^^^
  File "C:\Users\My_PC\AppData\Local\Programs\Python\Python311\Lib\site-packages\django\views\decorators\cache.py", line 62, in _wrapper_view_func
    response = view_func(request, *args, **kwargs)
               ^^^^^^^^^^^^^^^^^^^^^^^^^^^^^^^^^^^
  File "C:\Users\My_PC\AppData\Local\Programs\Python\Python311\Lib\site-packages\django\contrib\admin\sites.py", line 441, in login
    return LoginView.as_view(**defaults)(request)
           ^^^^^^^^^^^^^^^^^^^^^^^^^^^^^^^^^^^^^^
  File "C:\Users\My_PC\AppData\Local\Programs\Python\Python311\Lib\site-packages\django\views\generic\base.py", line 104, in view
    return self.dispatch(request, *args, **kwargs)
           ^^^^^^^^^^^^^^^^^^^^^^^^^^^^^^^^^^^^^^^
  File "C:\Users\My_PC\AppData\Local\Programs\Python\Python311\Lib\site-packages\django\utils\decorators.py", line 46, in _wrapper
    return bound_method(*args, **kwargs)
           ^^^^^^^^^^^^^^^^^^^^^^^^^^^^^
  File "C:\Users\My_PC\AppData\Local\Programs\Python\Python311\Lib\site-packages\django\views\decorators\debug.py", line 92, in sensitive_post_parameters_wrapper
    return view(request, *args, **kwargs)
           ^^^^^^^^^^^^^^^^^^^^^^^^^^^^^^
  File "C:\Users\My_PC\AppData\Local\Programs\Python\Python311\Lib\site-packages\django\utils\decorators.py", line 46, in _wrapper
    return bound_method(*args, **kwargs)
           ^^^^^^^^^^^^^^^^^^^^^^^^^^^^^
  File "C:\Users\My_PC\AppData\Local\Programs\Python\Python311\Lib\site-packages\django\utils\decorators.py", line 134, in _wrapper_view
    response = view_func(request, *args, **kwargs)
               ^^^^^^^^^^^^^^^^^^^^^^^^^^^^^^^^^^^
  File "C:\Users\My_PC\AppData\Local\Programs\Python\Python311\Lib\site-packages\django\utils\decorators.py", line 46, in _wrapper
    return bound_method(*args, **kwargs)
           ^^^^^^^^^^^^^^^^^^^^^^^^^^^^^
  File "C:\Users\My_PC\AppData\Local\Programs\Python\Python311\Lib\site-packages\django\views\decorators\cache.py", line 62, in _wrapper_view_func
    response = view_func(request, *args, **kwargs)
               ^^^^^^^^^^^^^^^^^^^^^^^^^^^^^^^^^^^
  File "C:\Users\My_PC\AppData\Local\Programs\Python\Python311\Lib\site-packages\django\contrib\auth\views.py", line 90, in dispatch
    return super().dispatch(request, *args, **kwargs)
           ^^^^^^^^^^^^^^^^^^^^^^^^^^^^^^^^^^^^^^^^^^
  File "C:\Users\My_PC\AppData\Local\Programs\Python\Python311\Lib\site-packages\django\views\generic\base.py", line 143, in dispatch
    return handler(request, *args, **kwargs)
           ^^^^^^^^^^^^^^^^^^^^^^^^^^^^^^^^^
  File "C:\Users\My_PC\AppData\Local\Programs\Python\Python311\Lib\site-packages\django\views\generic\edit.py", line 153, in post
    return self.form_valid(form)
           ^^^^^^^^^^^^^^^^^^^^^
  File "C:\Users\My_PC\AppData\Local\Programs\Python\Python311\Lib\site-packages\django\contrib\auth\views.py", line 109, in form_valid
    auth_login(self.request, form.get_user())
  File "C:\Users\My_PC\AppData\Local\Programs\Python\Python311\Lib\site-packages\django\contrib\auth\__init__.py", line 144, in login
    user_logged_in.send(sender=user.__class__, request=request, user=user)
  File "C:\Users\My_PC\AppData\Local\Programs\Python\Python311\Lib\site-packages\django\dispatch\dispatcher.py", line 176, in send
    return [
           ^
  File "C:\Users\My_PC\AppData\Local\Programs\Python\Python311\Lib\site-packages\django\dispatch\dispatcher.py", line 177, in <listcomp>
    (receiver, receiver(signal=self, sender=sender, **named))
               ^^^^^^^^^^^^^^^^^^^^^^^^^^^^^^^^^^^^^^^^^^^^^
  File "C:\Users\My_PC\AppData\Local\Programs\Python\Python311\Lib\site-packages\django\contrib\auth\models.py", line 23, in update_last_login
    user.save(update_fields=["last_login"])
  File "C:\Users\My_PC\AppData\Local\Programs\Python\Python311\Lib\site-packages\django\contrib\auth\base_user.py", line 76, in save
    super().save(*args, **kwargs)
  File "C:\Users\My_PC\AppData\Local\Programs\Python\Python311\Lib\site-packages\django\db\models\base.py", line 814, in save
    self.save_base(
  File "C:\Users\My_PC\AppData\Local\Programs\Python\Python311\Lib\site-packages\django\db\models\base.py", line 892, in save_base
    post_save.send(
  File "C:\Users\My_PC\AppData\Local\Programs\Python\Python311\Lib\site-packages\django\dispatch\dispatcher.py", line 176, in send
    return [
           ^
  File "C:\Users\My_PC\AppData\Local\Programs\Python\Python311\Lib\site-packages\django\dispatch\dispatcher.py", line 177, in <listcomp>
    (receiver, receiver(signal=self, sender=sender, **named))
               ^^^^^^^^^^^^^^^^^^^^^^^^^^^^^^^^^^^^^^^^^^^^^
  File "C:\Users\My_PC\Desktop\nosedive-master\main\models.py", line 22, in save_user_profile
    instance.profile.save()
    ^^^^^^^^^^^^^^^^
  File "C:\Users\My_PC\AppData\Local\Programs\Python\Python311\Lib\site-packages\django\db\models\fields\related_descriptors.py", line 492, in __get__
    raise self.RelatedObjectDoesNotExist(
django.contrib.auth.models.User.profile.RelatedObjectDoesNotExist: User has no profile.
2023-10-27 16:09:13,579 [ERROR]- Internal Server Error: /admin/login/
Traceback (most recent call last):
  File "C:\Users\My_PC\AppData\Local\Programs\Python\Python311\Lib\site-packages\django\core\handlers\exception.py", line 55, in inner
    response = get_response(request)
               ^^^^^^^^^^^^^^^^^^^^^
  File "C:\Users\My_PC\AppData\Local\Programs\Python\Python311\Lib\site-packages\django\core\handlers\base.py", line 197, in _get_response
    response = wrapped_callback(request, *callback_args, **callback_kwargs)
               ^^^^^^^^^^^^^^^^^^^^^^^^^^^^^^^^^^^^^^^^^^^^^^^^^^^^^^^^^^^^
  File "C:\Users\My_PC\AppData\Local\Programs\Python\Python311\Lib\site-packages\django\utils\decorators.py", line 46, in _wrapper
    return bound_method(*args, **kwargs)
           ^^^^^^^^^^^^^^^^^^^^^^^^^^^^^
  File "C:\Users\My_PC\AppData\Local\Programs\Python\Python311\Lib\site-packages\django\views\decorators\cache.py", line 62, in _wrapper_view_func
    response = view_func(request, *args, **kwargs)
               ^^^^^^^^^^^^^^^^^^^^^^^^^^^^^^^^^^^
  File "C:\Users\My_PC\AppData\Local\Programs\Python\Python311\Lib\site-packages\django\contrib\admin\sites.py", line 441, in login
    return LoginView.as_view(**defaults)(request)
           ^^^^^^^^^^^^^^^^^^^^^^^^^^^^^^^^^^^^^^
  File "C:\Users\My_PC\AppData\Local\Programs\Python\Python311\Lib\site-packages\django\views\generic\base.py", line 104, in view
    return self.dispatch(request, *args, **kwargs)
           ^^^^^^^^^^^^^^^^^^^^^^^^^^^^^^^^^^^^^^^
  File "C:\Users\My_PC\AppData\Local\Programs\Python\Python311\Lib\site-packages\django\utils\decorators.py", line 46, in _wrapper
    return bound_method(*args, **kwargs)
           ^^^^^^^^^^^^^^^^^^^^^^^^^^^^^
  File "C:\Users\My_PC\AppData\Local\Programs\Python\Python311\Lib\site-packages\django\views\decorators\debug.py", line 92, in sensitive_post_parameters_wrapper
    return view(request, *args, **kwargs)
           ^^^^^^^^^^^^^^^^^^^^^^^^^^^^^^
  File "C:\Users\My_PC\AppData\Local\Programs\Python\Python311\Lib\site-packages\django\utils\decorators.py", line 46, in _wrapper
    return bound_method(*args, **kwargs)
           ^^^^^^^^^^^^^^^^^^^^^^^^^^^^^
  File "C:\Users\My_PC\AppData\Local\Programs\Python\Python311\Lib\site-packages\django\utils\decorators.py", line 134, in _wrapper_view
    response = view_func(request, *args, **kwargs)
               ^^^^^^^^^^^^^^^^^^^^^^^^^^^^^^^^^^^
  File "C:\Users\My_PC\AppData\Local\Programs\Python\Python311\Lib\site-packages\django\utils\decorators.py", line 46, in _wrapper
    return bound_method(*args, **kwargs)
           ^^^^^^^^^^^^^^^^^^^^^^^^^^^^^
  File "C:\Users\My_PC\AppData\Local\Programs\Python\Python311\Lib\site-packages\django\views\decorators\cache.py", line 62, in _wrapper_view_func
    response = view_func(request, *args, **kwargs)
               ^^^^^^^^^^^^^^^^^^^^^^^^^^^^^^^^^^^
  File "C:\Users\My_PC\AppData\Local\Programs\Python\Python311\Lib\site-packages\django\contrib\auth\views.py", line 90, in dispatch
    return super().dispatch(request, *args, **kwargs)
           ^^^^^^^^^^^^^^^^^^^^^^^^^^^^^^^^^^^^^^^^^^
  File "C:\Users\My_PC\AppData\Local\Programs\Python\Python311\Lib\site-packages\django\views\generic\base.py", line 143, in dispatch
    return handler(request, *args, **kwargs)
           ^^^^^^^^^^^^^^^^^^^^^^^^^^^^^^^^^
  File "C:\Users\My_PC\AppData\Local\Programs\Python\Python311\Lib\site-packages\django\views\generic\edit.py", line 153, in post
    return self.form_valid(form)
           ^^^^^^^^^^^^^^^^^^^^^
  File "C:\Users\My_PC\AppData\Local\Programs\Python\Python311\Lib\site-packages\django\contrib\auth\views.py", line 109, in form_valid
    auth_login(self.request, form.get_user())
  File "C:\Users\My_PC\AppData\Local\Programs\Python\Python311\Lib\site-packages\django\contrib\auth\__init__.py", line 144, in login
    user_logged_in.send(sender=user.__class__, request=request, user=user)
  File "C:\Users\My_PC\AppData\Local\Programs\Python\Python311\Lib\site-packages\django\dispatch\dispatcher.py", line 176, in send
    return [
           ^
  File "C:\Users\My_PC\AppData\Local\Programs\Python\Python311\Lib\site-packages\django\dispatch\dispatcher.py", line 177, in <listcomp>
    (receiver, receiver(signal=self, sender=sender, **named))
               ^^^^^^^^^^^^^^^^^^^^^^^^^^^^^^^^^^^^^^^^^^^^^
  File "C:\Users\My_PC\AppData\Local\Programs\Python\Python311\Lib\site-packages\django\contrib\auth\models.py", line 23, in update_last_login
    user.save(update_fields=["last_login"])
  File "C:\Users\My_PC\AppData\Local\Programs\Python\Python311\Lib\site-packages\django\contrib\auth\base_user.py", line 76, in save
    super().save(*args, **kwargs)
  File "C:\Users\My_PC\AppData\Local\Programs\Python\Python311\Lib\site-packages\django\db\models\base.py", line 814, in save
    self.save_base(
  File "C:\Users\My_PC\AppData\Local\Programs\Python\Python311\Lib\site-packages\django\db\models\base.py", line 892, in save_base
    post_save.send(
  File "C:\Users\My_PC\AppData\Local\Programs\Python\Python311\Lib\site-packages\django\dispatch\dispatcher.py", line 176, in send
    return [
           ^
  File "C:\Users\My_PC\AppData\Local\Programs\Python\Python311\Lib\site-packages\django\dispatch\dispatcher.py", line 177, in <listcomp>
    (receiver, receiver(signal=self, sender=sender, **named))
               ^^^^^^^^^^^^^^^^^^^^^^^^^^^^^^^^^^^^^^^^^^^^^
  File "C:\Users\My_PC\Desktop\nosedive-master\main\models.py", line 22, in save_user_profile
    instance.profile.save()
    ^^^^^^^^^^^^^^^^
  File "C:\Users\My_PC\AppData\Local\Programs\Python\Python311\Lib\site-packages\django\db\models\fields\related_descriptors.py", line 492, in __get__
    raise self.RelatedObjectDoesNotExist(
django.contrib.auth.models.User.profile.RelatedObjectDoesNotExist: User has no profile.
2023-10-27 16:09:30,931 [ERROR]- Internal Server Error: /
Traceback (most recent call last):
  File "C:\Users\My_PC\AppData\Local\Programs\Python\Python311\Lib\site-packages\django\core\handlers\exception.py", line 55, in inner
    response = get_response(request)
               ^^^^^^^^^^^^^^^^^^^^^
  File "C:\Users\My_PC\AppData\Local\Programs\Python\Python311\Lib\site-packages\django\core\handlers\base.py", line 197, in _get_response
    response = wrapped_callback(request, *callback_args, **callback_kwargs)
               ^^^^^^^^^^^^^^^^^^^^^^^^^^^^^^^^^^^^^^^^^^^^^^^^^^^^^^^^^^^^
  File "C:\Users\My_PC\AppData\Local\Programs\Python\Python311\Lib\site-packages\django\views\generic\base.py", line 104, in view
    return self.dispatch(request, *args, **kwargs)
           ^^^^^^^^^^^^^^^^^^^^^^^^^^^^^^^^^^^^^^^
  File "C:\Users\My_PC\AppData\Local\Programs\Python\Python311\Lib\site-packages\django\views\generic\base.py", line 143, in dispatch
    return handler(request, *args, **kwargs)
           ^^^^^^^^^^^^^^^^^^^^^^^^^^^^^^^^^
  File "C:\Users\My_PC\Desktop\nosedive-master\main\views.py", line 51, in post
    current_rating = rated_user.profile.rating
                     ^^^^^^^^^^^^^^^^^^
  File "C:\Users\My_PC\AppData\Local\Programs\Python\Python311\Lib\site-packages\django\db\models\fields\related_descriptors.py", line 492, in __get__
    raise self.RelatedObjectDoesNotExist(
django.contrib.auth.models.User.profile.RelatedObjectDoesNotExist: User has no profile.
2023-10-27 16:12:40,948 [WARNING]- Bad Request: /
2023-10-27 16:12:41,372 [WARNING]- Bad Request: /favicon.ico
2023-10-27 16:17:41,213 [ERROR]- Internal Server Error: /
Traceback (most recent call last):
  File "C:\Users\My_PC\AppData\Local\Programs\Python\Python311\Lib\site-packages\django\core\handlers\exception.py", line 55, in inner
    response = get_response(request)
               ^^^^^^^^^^^^^^^^^^^^^
  File "C:\Users\My_PC\AppData\Local\Programs\Python\Python311\Lib\site-packages\django\core\handlers\base.py", line 220, in _get_response
    response = response.render()
               ^^^^^^^^^^^^^^^^^
  File "C:\Users\My_PC\AppData\Local\Programs\Python\Python311\Lib\site-packages\django\template\response.py", line 114, in render
    self.content = self.rendered_content
                   ^^^^^^^^^^^^^^^^^^^^^
  File "C:\Users\My_PC\AppData\Local\Programs\Python\Python311\Lib\site-packages\django\template\response.py", line 90, in rendered_content
    template = self.resolve_template(self.template_name)
               ^^^^^^^^^^^^^^^^^^^^^^^^^^^^^^^^^^^^^^^^^
  File "C:\Users\My_PC\AppData\Local\Programs\Python\Python311\Lib\site-packages\django\template\response.py", line 72, in resolve_template
    return select_template(template, using=self.using)
           ^^^^^^^^^^^^^^^^^^^^^^^^^^^^^^^^^^^^^^^^^^^
  File "C:\Users\My_PC\AppData\Local\Programs\Python\Python311\Lib\site-packages\django\template\loader.py", line 42, in select_template
    return engine.get_template(template_name)
           ^^^^^^^^^^^^^^^^^^^^^^^^^^^^^^^^^^
  File "C:\Users\My_PC\AppData\Local\Programs\Python\Python311\Lib\site-packages\django\template\backends\django.py", line 33, in get_template
    return Template(self.engine.get_template(template_name), self)
                    ^^^^^^^^^^^^^^^^^^^^^^^^^^^^^^^^^^^^^^^
  File "C:\Users\My_PC\AppData\Local\Programs\Python\Python311\Lib\site-packages\django\template\engine.py", line 175, in get_template
    template, origin = self.find_template(template_name)
                       ^^^^^^^^^^^^^^^^^^^^^^^^^^^^^^^^^
  File "C:\Users\My_PC\AppData\Local\Programs\Python\Python311\Lib\site-packages\django\template\engine.py", line 157, in find_template
    template = loader.get_template(name, skip=skip)
               ^^^^^^^^^^^^^^^^^^^^^^^^^^^^^^^^^^^^
  File "C:\Users\My_PC\AppData\Local\Programs\Python\Python311\Lib\site-packages\django\template\loaders\cached.py", line 57, in get_template
    template = super().get_template(template_name, skip)
               ^^^^^^^^^^^^^^^^^^^^^^^^^^^^^^^^^^^^^^^^^
  File "C:\Users\My_PC\AppData\Local\Programs\Python\Python311\Lib\site-packages\django\template\loaders\base.py", line 28, in get_template
    return Template(
           ^^^^^^^^^
  File "C:\Users\My_PC\AppData\Local\Programs\Python\Python311\Lib\site-packages\django\template\base.py", line 154, in __init__
    self.nodelist = self.compile_nodelist()
                    ^^^^^^^^^^^^^^^^^^^^^^^
  File "C:\Users\My_PC\AppData\Local\Programs\Python\Python311\Lib\site-packages\django\template\base.py", line 200, in compile_nodelist
    return parser.parse()
           ^^^^^^^^^^^^^^
  File "C:\Users\My_PC\AppData\Local\Programs\Python\Python311\Lib\site-packages\django\template\base.py", line 513, in parse
    raise self.error(token, e)
  File "C:\Users\My_PC\AppData\Local\Programs\Python\Python311\Lib\site-packages\django\template\base.py", line 511, in parse
    compiled_result = compile_func(self, token)
                      ^^^^^^^^^^^^^^^^^^^^^^^^^
  File "C:\Users\My_PC\AppData\Local\Programs\Python\Python311\Lib\site-packages\django\template\loader_tags.py", line 293, in do_extends
    nodelist = parser.parse()
               ^^^^^^^^^^^^^^
  File "C:\Users\My_PC\AppData\Local\Programs\Python\Python311\Lib\site-packages\django\template\base.py", line 513, in parse
    raise self.error(token, e)
  File "C:\Users\My_PC\AppData\Local\Programs\Python\Python311\Lib\site-packages\django\template\base.py", line 511, in parse
    compiled_result = compile_func(self, token)
                      ^^^^^^^^^^^^^^^^^^^^^^^^^
  File "C:\Users\My_PC\AppData\Local\Programs\Python\Python311\Lib\site-packages\django\template\loader_tags.py", line 232, in do_block
    nodelist = parser.parse(("endblock",))
               ^^^^^^^^^^^^^^^^^^^^^^^^^^^
  File "C:\Users\My_PC\AppData\Local\Programs\Python\Python311\Lib\site-packages\django\template\base.py", line 513, in parse
    raise self.error(token, e)
  File "C:\Users\My_PC\AppData\Local\Programs\Python\Python311\Lib\site-packages\django\template\base.py", line 511, in parse
    compiled_result = compile_func(self, token)
                      ^^^^^^^^^^^^^^^^^^^^^^^^^
  File "C:\Users\My_PC\AppData\Local\Programs\Python\Python311\Lib\site-packages\django\template\defaulttags.py", line 953, in do_if
    nodelist = parser.parse(("elif", "else", "endif"))
               ^^^^^^^^^^^^^^^^^^^^^^^^^^^^^^^^^^^^^^^
  File "C:\Users\My_PC\AppData\Local\Programs\Python\Python311\Lib\site-packages\django\template\base.py", line 484, in parse
    raise self.error(token, e)
  File "C:\Users\My_PC\AppData\Local\Programs\Python\Python311\Lib\site-packages\django\template\base.py", line 482, in parse
    filter_expression = self.compile_filter(token.contents)
                        ^^^^^^^^^^^^^^^^^^^^^^^^^^^^^^^^^^^
  File "C:\Users\My_PC\AppData\Local\Programs\Python\Python311\Lib\site-packages\django\template\base.py", line 600, in compile_filter
    return FilterExpression(token, self)
           ^^^^^^^^^^^^^^^^^^^^^^^^^^^^^
  File "C:\Users\My_PC\AppData\Local\Programs\Python\Python311\Lib\site-packages\django\template\base.py", line 703, in __init__
    raise TemplateSyntaxError(
django.template.exceptions.TemplateSyntaxError: Could not parse the remainder: '(users.first_name)' from 'print(users.first_name)'
2023-10-27 16:19:52,195 [ERROR]- Internal Server Error: /
Traceback (most recent call last):
  File "C:\Users\My_PC\AppData\Local\Programs\Python\Python311\Lib\site-packages\django\core\handlers\exception.py", line 55, in inner
    response = get_response(request)
               ^^^^^^^^^^^^^^^^^^^^^
  File "C:\Users\My_PC\AppData\Local\Programs\Python\Python311\Lib\site-packages\django\core\handlers\base.py", line 220, in _get_response
    response = response.render()
               ^^^^^^^^^^^^^^^^^
  File "C:\Users\My_PC\AppData\Local\Programs\Python\Python311\Lib\site-packages\django\template\response.py", line 114, in render
    self.content = self.rendered_content
                   ^^^^^^^^^^^^^^^^^^^^^
  File "C:\Users\My_PC\AppData\Local\Programs\Python\Python311\Lib\site-packages\django\template\response.py", line 90, in rendered_content
    template = self.resolve_template(self.template_name)
               ^^^^^^^^^^^^^^^^^^^^^^^^^^^^^^^^^^^^^^^^^
  File "C:\Users\My_PC\AppData\Local\Programs\Python\Python311\Lib\site-packages\django\template\response.py", line 72, in resolve_template
    return select_template(template, using=self.using)
           ^^^^^^^^^^^^^^^^^^^^^^^^^^^^^^^^^^^^^^^^^^^
  File "C:\Users\My_PC\AppData\Local\Programs\Python\Python311\Lib\site-packages\django\template\loader.py", line 42, in select_template
    return engine.get_template(template_name)
           ^^^^^^^^^^^^^^^^^^^^^^^^^^^^^^^^^^
  File "C:\Users\My_PC\AppData\Local\Programs\Python\Python311\Lib\site-packages\django\template\backends\django.py", line 33, in get_template
    return Template(self.engine.get_template(template_name), self)
                    ^^^^^^^^^^^^^^^^^^^^^^^^^^^^^^^^^^^^^^^
  File "C:\Users\My_PC\AppData\Local\Programs\Python\Python311\Lib\site-packages\django\template\engine.py", line 175, in get_template
    template, origin = self.find_template(template_name)
                       ^^^^^^^^^^^^^^^^^^^^^^^^^^^^^^^^^
  File "C:\Users\My_PC\AppData\Local\Programs\Python\Python311\Lib\site-packages\django\template\engine.py", line 157, in find_template
    template = loader.get_template(name, skip=skip)
               ^^^^^^^^^^^^^^^^^^^^^^^^^^^^^^^^^^^^
  File "C:\Users\My_PC\AppData\Local\Programs\Python\Python311\Lib\site-packages\django\template\loaders\cached.py", line 57, in get_template
    template = super().get_template(template_name, skip)
               ^^^^^^^^^^^^^^^^^^^^^^^^^^^^^^^^^^^^^^^^^
  File "C:\Users\My_PC\AppData\Local\Programs\Python\Python311\Lib\site-packages\django\template\loaders\base.py", line 28, in get_template
    return Template(
           ^^^^^^^^^
  File "C:\Users\My_PC\AppData\Local\Programs\Python\Python311\Lib\site-packages\django\template\base.py", line 154, in __init__
    self.nodelist = self.compile_nodelist()
                    ^^^^^^^^^^^^^^^^^^^^^^^
  File "C:\Users\My_PC\AppData\Local\Programs\Python\Python311\Lib\site-packages\django\template\base.py", line 200, in compile_nodelist
    return parser.parse()
           ^^^^^^^^^^^^^^
  File "C:\Users\My_PC\AppData\Local\Programs\Python\Python311\Lib\site-packages\django\template\base.py", line 513, in parse
    raise self.error(token, e)
  File "C:\Users\My_PC\AppData\Local\Programs\Python\Python311\Lib\site-packages\django\template\base.py", line 511, in parse
    compiled_result = compile_func(self, token)
                      ^^^^^^^^^^^^^^^^^^^^^^^^^
  File "C:\Users\My_PC\AppData\Local\Programs\Python\Python311\Lib\site-packages\django\template\loader_tags.py", line 293, in do_extends
    nodelist = parser.parse()
               ^^^^^^^^^^^^^^
  File "C:\Users\My_PC\AppData\Local\Programs\Python\Python311\Lib\site-packages\django\template\base.py", line 513, in parse
    raise self.error(token, e)
  File "C:\Users\My_PC\AppData\Local\Programs\Python\Python311\Lib\site-packages\django\template\base.py", line 511, in parse
    compiled_result = compile_func(self, token)
                      ^^^^^^^^^^^^^^^^^^^^^^^^^
  File "C:\Users\My_PC\AppData\Local\Programs\Python\Python311\Lib\site-packages\django\template\loader_tags.py", line 232, in do_block
    nodelist = parser.parse(("endblock",))
               ^^^^^^^^^^^^^^^^^^^^^^^^^^^
  File "C:\Users\My_PC\AppData\Local\Programs\Python\Python311\Lib\site-packages\django\template\base.py", line 513, in parse
    raise self.error(token, e)
  File "C:\Users\My_PC\AppData\Local\Programs\Python\Python311\Lib\site-packages\django\template\base.py", line 511, in parse
    compiled_result = compile_func(self, token)
                      ^^^^^^^^^^^^^^^^^^^^^^^^^
  File "C:\Users\My_PC\AppData\Local\Programs\Python\Python311\Lib\site-packages\django\template\defaulttags.py", line 953, in do_if
    nodelist = parser.parse(("elif", "else", "endif"))
               ^^^^^^^^^^^^^^^^^^^^^^^^^^^^^^^^^^^^^^^
  File "C:\Users\My_PC\AppData\Local\Programs\Python\Python311\Lib\site-packages\django\template\base.py", line 484, in parse
    raise self.error(token, e)
  File "C:\Users\My_PC\AppData\Local\Programs\Python\Python311\Lib\site-packages\django\template\base.py", line 482, in parse
    filter_expression = self.compile_filter(token.contents)
                        ^^^^^^^^^^^^^^^^^^^^^^^^^^^^^^^^^^^
  File "C:\Users\My_PC\AppData\Local\Programs\Python\Python311\Lib\site-packages\django\template\base.py", line 600, in compile_filter
    return FilterExpression(token, self)
           ^^^^^^^^^^^^^^^^^^^^^^^^^^^^^
  File "C:\Users\My_PC\AppData\Local\Programs\Python\Python311\Lib\site-packages\django\template\base.py", line 699, in __init__
    self.args_check(filter_name, filter_func, args)
  File "C:\Users\My_PC\AppData\Local\Programs\Python\Python311\Lib\site-packages\django\template\base.py", line 761, in args_check
    raise TemplateSyntaxError(
django.template.exceptions.TemplateSyntaxError: stringformat requires 2 arguments, 1 provided
2023-10-27 16:19:53,139 [ERROR]- Internal Server Error: /
Traceback (most recent call last):
  File "C:\Users\My_PC\AppData\Local\Programs\Python\Python311\Lib\site-packages\django\core\handlers\exception.py", line 55, in inner
    response = get_response(request)
               ^^^^^^^^^^^^^^^^^^^^^
  File "C:\Users\My_PC\AppData\Local\Programs\Python\Python311\Lib\site-packages\django\core\handlers\base.py", line 220, in _get_response
    response = response.render()
               ^^^^^^^^^^^^^^^^^
  File "C:\Users\My_PC\AppData\Local\Programs\Python\Python311\Lib\site-packages\django\template\response.py", line 114, in render
    self.content = self.rendered_content
                   ^^^^^^^^^^^^^^^^^^^^^
  File "C:\Users\My_PC\AppData\Local\Programs\Python\Python311\Lib\site-packages\django\template\response.py", line 90, in rendered_content
    template = self.resolve_template(self.template_name)
               ^^^^^^^^^^^^^^^^^^^^^^^^^^^^^^^^^^^^^^^^^
  File "C:\Users\My_PC\AppData\Local\Programs\Python\Python311\Lib\site-packages\django\template\response.py", line 72, in resolve_template
    return select_template(template, using=self.using)
           ^^^^^^^^^^^^^^^^^^^^^^^^^^^^^^^^^^^^^^^^^^^
  File "C:\Users\My_PC\AppData\Local\Programs\Python\Python311\Lib\site-packages\django\template\loader.py", line 42, in select_template
    return engine.get_template(template_name)
           ^^^^^^^^^^^^^^^^^^^^^^^^^^^^^^^^^^
  File "C:\Users\My_PC\AppData\Local\Programs\Python\Python311\Lib\site-packages\django\template\backends\django.py", line 33, in get_template
    return Template(self.engine.get_template(template_name), self)
                    ^^^^^^^^^^^^^^^^^^^^^^^^^^^^^^^^^^^^^^^
  File "C:\Users\My_PC\AppData\Local\Programs\Python\Python311\Lib\site-packages\django\template\engine.py", line 175, in get_template
    template, origin = self.find_template(template_name)
                       ^^^^^^^^^^^^^^^^^^^^^^^^^^^^^^^^^
  File "C:\Users\My_PC\AppData\Local\Programs\Python\Python311\Lib\site-packages\django\template\engine.py", line 157, in find_template
    template = loader.get_template(name, skip=skip)
               ^^^^^^^^^^^^^^^^^^^^^^^^^^^^^^^^^^^^
  File "C:\Users\My_PC\AppData\Local\Programs\Python\Python311\Lib\site-packages\django\template\loaders\cached.py", line 57, in get_template
    template = super().get_template(template_name, skip)
               ^^^^^^^^^^^^^^^^^^^^^^^^^^^^^^^^^^^^^^^^^
  File "C:\Users\My_PC\AppData\Local\Programs\Python\Python311\Lib\site-packages\django\template\loaders\base.py", line 28, in get_template
    return Template(
           ^^^^^^^^^
  File "C:\Users\My_PC\AppData\Local\Programs\Python\Python311\Lib\site-packages\django\template\base.py", line 154, in __init__
    self.nodelist = self.compile_nodelist()
                    ^^^^^^^^^^^^^^^^^^^^^^^
  File "C:\Users\My_PC\AppData\Local\Programs\Python\Python311\Lib\site-packages\django\template\base.py", line 200, in compile_nodelist
    return parser.parse()
           ^^^^^^^^^^^^^^
  File "C:\Users\My_PC\AppData\Local\Programs\Python\Python311\Lib\site-packages\django\template\base.py", line 513, in parse
    raise self.error(token, e)
  File "C:\Users\My_PC\AppData\Local\Programs\Python\Python311\Lib\site-packages\django\template\base.py", line 511, in parse
    compiled_result = compile_func(self, token)
                      ^^^^^^^^^^^^^^^^^^^^^^^^^
  File "C:\Users\My_PC\AppData\Local\Programs\Python\Python311\Lib\site-packages\django\template\loader_tags.py", line 293, in do_extends
    nodelist = parser.parse()
               ^^^^^^^^^^^^^^
  File "C:\Users\My_PC\AppData\Local\Programs\Python\Python311\Lib\site-packages\django\template\base.py", line 513, in parse
    raise self.error(token, e)
  File "C:\Users\My_PC\AppData\Local\Programs\Python\Python311\Lib\site-packages\django\template\base.py", line 511, in parse
    compiled_result = compile_func(self, token)
                      ^^^^^^^^^^^^^^^^^^^^^^^^^
  File "C:\Users\My_PC\AppData\Local\Programs\Python\Python311\Lib\site-packages\django\template\loader_tags.py", line 232, in do_block
    nodelist = parser.parse(("endblock",))
               ^^^^^^^^^^^^^^^^^^^^^^^^^^^
  File "C:\Users\My_PC\AppData\Local\Programs\Python\Python311\Lib\site-packages\django\template\base.py", line 513, in parse
    raise self.error(token, e)
  File "C:\Users\My_PC\AppData\Local\Programs\Python\Python311\Lib\site-packages\django\template\base.py", line 511, in parse
    compiled_result = compile_func(self, token)
                      ^^^^^^^^^^^^^^^^^^^^^^^^^
  File "C:\Users\My_PC\AppData\Local\Programs\Python\Python311\Lib\site-packages\django\template\defaulttags.py", line 953, in do_if
    nodelist = parser.parse(("elif", "else", "endif"))
               ^^^^^^^^^^^^^^^^^^^^^^^^^^^^^^^^^^^^^^^
  File "C:\Users\My_PC\AppData\Local\Programs\Python\Python311\Lib\site-packages\django\template\base.py", line 484, in parse
    raise self.error(token, e)
  File "C:\Users\My_PC\AppData\Local\Programs\Python\Python311\Lib\site-packages\django\template\base.py", line 482, in parse
    filter_expression = self.compile_filter(token.contents)
                        ^^^^^^^^^^^^^^^^^^^^^^^^^^^^^^^^^^^
  File "C:\Users\My_PC\AppData\Local\Programs\Python\Python311\Lib\site-packages\django\template\base.py", line 600, in compile_filter
    return FilterExpression(token, self)
           ^^^^^^^^^^^^^^^^^^^^^^^^^^^^^
  File "C:\Users\My_PC\AppData\Local\Programs\Python\Python311\Lib\site-packages\django\template\base.py", line 699, in __init__
    self.args_check(filter_name, filter_func, args)
  File "C:\Users\My_PC\AppData\Local\Programs\Python\Python311\Lib\site-packages\django\template\base.py", line 761, in args_check
    raise TemplateSyntaxError(
django.template.exceptions.TemplateSyntaxError: stringformat requires 2 arguments, 1 provided
2023-10-27 19:21:41,278 [WARNING]- Not Found: /favicon.ico
